Workbook

Sheet ЦТО
C1: класс | D1: Дата | E1: Задание 1 | M1: Задание 2 | W1: Задание 3 | AL1: ОБРАБОТКА ДЛЯ ВК | AT1: ОБРАБОТКА ДЛЯ СО и самооценки | BB1: ОБРАБОТКА ДЛЯ СО разница
E2: 1 | F2: 2 | G2: 3 | H2: 4 | I2: 5 | J2: 6 | K2: 7 | L2: 8 | M2: Счастье | N2: Горе | O2: Справедливость | P2: Обида | Q2: Дружба | R2: Ссора | S2: Доброта | T2: Злоба | U2: Скука | V2: Восхищение | W2: Душа | X2: Школа | Y2: Чтение | Z2: Математика | AA2: Русский яз | AB2: Английский яз | AC2: Исследование | AD2: Педагог | AE2: Одноклассники | AF2: Дом | AG2: Уроки | AH2: Свое | AI2: Наставник | AJ2: Одноклассники | AK2: Домашнее задание | AL2: место синего | AM2: место красного | AN2: место желтого | AO2: место коричневого | AP2: место зеленого | AQ2: место фиолетового | AR2: место серого | AS2: место черного | AT2: красный | AU2: желтый | AV2: зеленый | AW2: фиолетовый | AX2: синий | AY2: коричневый | AZ2: серый | BA2: черный | BB2: красный | BC2: желтый | BD2: зеленый | BE2: фиолетовый | BF2: синий | BG2: коричневый | BH2: серый | BI2: черный
A3: 1 | B3: А | C3: 2 а | AL3: =IF($BK$3=E3,1,IF($BK$3=F3,2,IF($BK$3=G3,3,IF($BK$3=H3,4,IF($BK$3=I3,5,IF($BK$3=J3,6,IF($BK$3=K3,7,IF($BK$3=L3,8,"")))))))) | AM3: =IF($BK$4=E3,1,IF($BK$4=F3,2,IF($BK$4=G3,3,IF($BK$4=H3,4,IF($BK$4=I3,5,IF($BK$4=J3,6,IF($BK$4=K3,7,IF($BK$4=L3,8,"")))))))) | AN3: =IF($BK$5=E3,1, IF($BK$5=F3,2, IF($BK$5=G3,3,IF($BK$5=H3,4, IF($BK$5=I3,5, IF($BK$5=J3,6, IF($BK$5=K3,7, IF($BK$5=L3,8,"")))))))) | AO3: =IF($BK$9=E3,1, IF($BK$9=F3,2, IF($BK$9=G3,3,IF($BK$9=H3,4, IF($BK$9=I3,5, IF($BK$9=J3,6, IF($BK$9=K3,7,IF($BK$9=L3,8,"")))))))) | AP3: =IF($BK$6=E3,1,IF($BK$6=F3,2,IF($BK$6=G3,3,IF($BK$6=H3,4,IF($BK$6=I3,5,IF($BK$6=J3,6,IF($BK$6=K3,7,IF($BK$6=L3,8,"")))))))) | AQ3: =IF($BK$7=E3,1,IF($BK$7=F3,2,IF($BK$7=G3,3,IF($BK$7=H3,4,IF($BK$7=I3,5,IF($BK$7=J3,6,IF($BK$7=K3,7,IF($BK$7=L3,8,"")))))))) | AR3: =IF($BK$8=E3,1, IF($BK$8=F3,2, IF($BK$8=G3,3,IF($BK$8=H3,4, IF($BK$8=I3,5, IF($BK$8=J3,6, IF($BK$8=K3,7,IF($BK$8=L3,8,"")))))))) | AS3: =IF($BK$10=E3,1, IF($BK$10=F3,2, IF($BK$10=G3,3,IF($BK$10=H3,4, IF($BK$10=I3,5, IF($BK$10=J3,6, IF($BK$10=K3,7, IF($BK$10=L3,8,"")))))))) | AT3: =IF(AM3="","",AM3) | AU3: =IF(AN3="","",AN3) | AV3: =IF(AP3="","",AP3) | AW3: =IF(AQ3="","",AQ3) | AX3: =IF(AL3="","",AL3) | AY3: =IF(AO3="","",AO3) | AZ3: =IF(AR3="","",AR3) | BA3: =IF(AS3="","",AS3) | BB3: =IF(AT3="","",ABS(AT3-1)) | BC3: =IF(AU3="","",ABS(AU3-2)) | BD3: =IF(AV3="","",ABS(AV3-3)) | BE3: =IF(AW3="","",ABS(AW3-4)) | BF3: =IF(AX3="","",ABS(AX3-5)) | BG3: =IF(AY3="","",ABS(AY3-6)) | BH3: =IF(AZ3="","",ABS(AZ3-7)) | BI3: =IF(L3="","",ABS(BA3-8)) | BJ3: 1 | BK3: синий | BL3: 1 | BM3: 5
A4: 2 | B4: Б | C4: 2 а | E4: фиолетовый | F4: синий | G4: красный | H4: черный | I4: зеленый | J4: желтый | K4: серый | L4: коричневый | M4: желтый | N4: синий | O4: зеленый | P4: черный | Q4: фиолетовый | R4: серый | S4: желтый | T4: коричневый | U4: серый | V4: красный | X4: серый | Y4: красный | Z4: синий | AA4: черный | AB4: коричневый | AC4: фиолетовый | AD4: красный | AE4: зеленый | AF4: красный | AG4: черный | AH4: черный | AL4: =IF($BK$3=E4,1,IF($BK$3=F4,2,IF($BK$3=G4,3,IF($BK$3=H4,4,IF($BK$3=I4,5,IF($BK$3=J4,6,IF($BK$3=K4,7,IF($BK$3=L4,8,"")))))))) -> 2 | AM4: =IF($BK$4=E4,1,IF($BK$4=F4,2,IF($BK$4=G4,3,IF($BK$4=H4,4,IF($BK$4=I4,5,IF($BK$4=J4,6,IF($BK$4=K4,7,IF($BK$4=L4,8,"")))))))) -> 3 | AN4: =IF($BK$5=E4,1, IF($BK$5=F4,2, IF($BK$5=G4,3,IF($BK$5=H4,4, IF($BK$5=I4,5, IF($BK$5=J4,6, IF($BK$5=K4,7, IF($BK$5=L4,8,"")))))))) -> 6 | AO4: =IF($BK$9=E4,1, IF($BK$9=F4,2, IF($BK$9=G4,3,IF($BK$9=H4,4, IF($BK$9=I4,5, IF($BK$9=J4,6, IF($BK$9=K4,7,IF($BK$9=L4,8,"")))))))) -> 8 | AP4: =IF($BK$6=E4,1,IF($BK$6=F4,2,IF($BK$6=G4,3,IF($BK$6=H4,4,IF($BK$6=I4,5,IF($BK$6=J4,6,IF($BK$6=K4,7,IF($BK$6=L4,8,"")))))))) -> 5 | AQ4: =IF($BK$7=E4,1,IF($BK$7=F4,2,IF($BK$7=G4,3,IF($BK$7=H4,4,IF($BK$7=I4,5,IF($BK$7=J4,6,IF($BK$7=K4,7,IF($BK$7=L4,8,"")))))))) -> 1 | AR4: =IF($BK$8=E4,1, IF($BK$8=F4,2, IF($BK$8=G4,3,IF($BK$8=H4,4, IF($BK$8=I4,5, IF($BK$8=J4,6, IF($BK$8=K4,7,IF($BK$8=L4,8,"")))))))) -> 7 | AS4: =IF($BK$10=E4,1, IF($BK$10=F4,2, IF($BK$10=G4,3,IF($BK$10=H4,4, IF($BK$10=I4,5, IF($BK$10=J4,6, IF($BK$10=K4,7, IF($BK$10=L4,8,"")))))))) -> 4 | AT4: =IF(AM4="","",AM4) -> 3 | AU4: =IF(AN4="","",AN4) -> 6 | AV4: =IF(AP4="","",AP4) -> 5 | AW4: =IF(AQ4="","",AQ4) -> 1 | AX4: =IF(AL4="","",AL4) -> 2 | AY4: =IF(AO4="","",AO4) -> 8 | AZ4: =IF(AR4="","",AR4) -> 7 | BA4: =IF(AS4="","",AS4) -> 4 | BB4: =IF(AT4="","",ABS(AT4-1)) -> 2 | BC4: =IF(AU4="","",ABS(AU4-2)) -> 4 | BD4: =IF(AV4="","",ABS(AV4-3)) -> 2 | BE4: =IF(AW4="","",ABS(AW4-4)) -> 3 | BF4: =IF(AX4="","",ABS(AX4-5)) -> 3 | BG4: =IF(AY4="","",ABS(AY4-6)) -> 2 | BH4: =IF(AZ4="","",ABS(AZ4-7)) -> 0 | BI4: =IF(L4="","",ABS(BA4-8)) -> 4 | BJ4: 3 | BK4: красный | BL4: 2 | BM4: 1
A5: 3 | B5: В | C5: 2 а | E5: фиолетовый | F5: синий | G5: зеленый | H5: черный | I5: серый | J5: желтый | K5: красный | L5: коричневый | M5: желтый | N5: синий | O5: зеленый | P5: черный | Q5: фиолетовый | R5: серый | S5: желтый | T5: коричневый | U5: серый | V5: красный | X5: серый | Y5: желтый | Z5: синий | AA5: черный | AB5: черный | AC5: фиолетовый | AD5: красный | AE5: фиолетовый | AF5: желтый | AG5: черный | AH5: зеленый | AL5: =IF($BK$3=E5,1,IF($BK$3=F5,2,IF($BK$3=G5,3,IF($BK$3=H5,4,IF($BK$3=I5,5,IF($BK$3=J5,6,IF($BK$3=K5,7,IF($BK$3=L5,8,"")))))))) -> 2 | AM5: =IF($BK$4=E5,1,IF($BK$4=F5,2,IF($BK$4=G5,3,IF($BK$4=H5,4,IF($BK$4=I5,5,IF($BK$4=J5,6,IF($BK$4=K5,7,IF($BK$4=L5,8,"")))))))) -> 7 | AN5: =IF($BK$5=E5,1, IF($BK$5=F5,2, IF($BK$5=G5,3,IF($BK$5=H5,4, IF($BK$5=I5,5, IF($BK$5=J5,6, IF($BK$5=K5,7, IF($BK$5=L5,8,"")))))))) -> 6 | AO5: =IF($BK$9=E5,1, IF($BK$9=F5,2, IF($BK$9=G5,3,IF($BK$9=H5,4, IF($BK$9=I5,5, IF($BK$9=J5,6, IF($BK$9=K5,7,IF($BK$9=L5,8,"")))))))) -> 8 | AP5: =IF($BK$6=E5,1,IF($BK$6=F5,2,IF($BK$6=G5,3,IF($BK$6=H5,4,IF($BK$6=I5,5,IF($BK$6=J5,6,IF($BK$6=K5,7,IF($BK$6=L5,8,"")))))))) -> 3 | AQ5: =IF($BK$7=E5,1,IF($BK$7=F5,2,IF($BK$7=G5,3,IF($BK$7=H5,4,IF($BK$7=I5,5,IF($BK$7=J5,6,IF($BK$7=K5,7,IF($BK$7=L5,8,"")))))))) -> 1 | AR5: =IF($BK$8=E5,1, IF($BK$8=F5,2, IF($BK$8=G5,3,IF($BK$8=H5,4, IF($BK$8=I5,5, IF($BK$8=J5,6, IF($BK$8=K5,7,IF($BK$8=L5,8,"")))))))) -> 5 | AS5: =IF($BK$10=E5,1, IF($BK$10=F5,2, IF($BK$10=G5,3,IF($BK$10=H5,4, IF($BK$10=I5,5, IF($BK$10=J5,6, IF($BK$10=K5,7, IF($BK$10=L5,8,"")))))))) -> 4 | AT5: =IF(AM5="","",AM5) -> 7 | AU5: =IF(AN5="","",AN5) -> 6 | AV5: =IF(AP5="","",AP5) -> 3 | AW5: =IF(AQ5="","",AQ5) -> 1 | AX5: =IF(AL5="","",AL5) -> 2 | AY5: =IF(AO5="","",AO5) -> 8 | AZ5: =IF(AR5="","",AR5) -> 5 | BA5: =IF(AS5="","",AS5) -> 4 | BB5: =IF(AT5="","",ABS(AT5-1)) -> 6 | BC5: =IF(AU5="","",ABS(AU5-2)) -> 4 | BD5: =IF(AV5="","",ABS(AV5-3)) -> 0 | BE5: =IF(AW5="","",ABS(AW5-4)) -> 3 | BF5: =IF(AX5="","",ABS(AX5-5)) -> 3 | BG5: =IF(AY5="","",ABS(AY5-6)) -> 2 | BH5: =IF(AZ5="","",ABS(AZ5-7)) -> 2 | BI5: =IF(L5="","",ABS(BA5-8)) -> 4 | BJ5: 4 | BK5: желтый | BL5: 3 | BM5: 2
A6: 4 | B6: Г | C6: 2 а | E6: красный | F6: черный | G6: желтый | H6: синий | I6: зеленый | J6: серый | K6: коричневый | L6: фиолетовый | M6: желтый | N6: синий | O6: серый | P6: черный | Q6: желтый | R6: коричневый | S6: желтый | T6: красный | U6: фиолетовый | V6: желтый | X6: черный | Y6: черный | Z6: черный | AA6: черный | AB6: черный | AC6: черный | AD6: черный | AE6: желтый | AF6: желтый | AG6: черный | AH6: желтый | AL6: =IF($BK$3=E6,1,IF($BK$3=F6,2,IF($BK$3=G6,3,IF($BK$3=H6,4,IF($BK$3=I6,5,IF($BK$3=J6,6,IF($BK$3=K6,7,IF($BK$3=L6,8,"")))))))) -> 4 | AM6: =IF($BK$4=E6,1,IF($BK$4=F6,2,IF($BK$4=G6,3,IF($BK$4=H6,4,IF($BK$4=I6,5,IF($BK$4=J6,6,IF($BK$4=K6,7,IF($BK$4=L6,8,"")))))))) -> 1 | AN6: =IF($BK$5=E6,1, IF($BK$5=F6,2, IF($BK$5=G6,3,IF($BK$5=H6,4, IF($BK$5=I6,5, IF($BK$5=J6,6, IF($BK$5=K6,7, IF($BK$5=L6,8,"")))))))) -> 3 | AO6: =IF($BK$9=E6,1, IF($BK$9=F6,2, IF($BK$9=G6,3,IF($BK$9=H6,4, IF($BK$9=I6,5, IF($BK$9=J6,6, IF($BK$9=K6,7,IF($BK$9=L6,8,"")))))))) -> 7 | AP6: =IF($BK$6=E6,1,IF($BK$6=F6,2,IF($BK$6=G6,3,IF($BK$6=H6,4,IF($BK$6=I6,5,IF($BK$6=J6,6,IF($BK$6=K6,7,IF($BK$6=L6,8,"")))))))) -> 5 | AQ6: =IF($BK$7=E6,1,IF($BK$7=F6,2,IF($BK$7=G6,3,IF($BK$7=H6,4,IF($BK$7=I6,5,IF($BK$7=J6,6,IF($BK$7=K6,7,IF($BK$7=L6,8,"")))))))) -> 8 | AR6: =IF($BK$8=E6,1, IF($BK$8=F6,2, IF($BK$8=G6,3,IF($BK$8=H6,4, IF($BK$8=I6,5, IF($BK$8=J6,6, IF($BK$8=K6,7,IF($BK$8=L6,8,"")))))))) -> 6 | AS6: =IF($BK$10=E6,1, IF($BK$10=F6,2, IF($BK$10=G6,3,IF($BK$10=H6,4, IF($BK$10=I6,5, IF($BK$10=J6,6, IF($BK$10=K6,7, IF($BK$10=L6,8,"")))))))) -> 2 | AT6: =IF(AM6="","",AM6) -> 1 | AU6: =IF(AN6="","",AN6) -> 3 | AV6: =IF(AP6="","",AP6) -> 5 | AW6: =IF(AQ6="","",AQ6) -> 8 | AX6: =IF(AL6="","",AL6) -> 4 | AY6: =IF(AO6="","",AO6) -> 7 | AZ6: =IF(AR6="","",AR6) -> 6 | BA6: =IF(AS6="","",AS6) -> 2 | BB6: =IF(AT6="","",ABS(AT6-1)) -> 0 | BC6: =IF(AU6="","",ABS(AU6-2)) -> 1 | BD6: =IF(AV6="","",ABS(AV6-3)) -> 2 | BE6: =IF(AW6="","",ABS(AW6-4)) -> 4 | BF6: =IF(AX6="","",ABS(AX6-5)) -> 1 | BG6: =IF(AY6="","",ABS(AY6-6)) -> 1 | BH6: =IF(AZ6="","",ABS(AZ6-7)) -> 1 | BI6: =IF(L6="","",ABS(BA6-8)) -> 6 | BJ6: 2 | BK6: зеленый | BL6: 4 | BM6: 3
A7: 5 | B7: Д | C7: 2 а | E7: красный | F7: черный | G7: зеленый | H7: желтый | I7: серый | J7: коричневый | K7: фиолетовый | L7: синий | M7: красный | N7: синий | O7: серый | P7: черный | Q7: красный | R7: черный | S7: красный | T7: серый | U7: фиолетовый | V7: желтый | X7: фиолетовый | Y7: желтый | Z7: синий | AA7: красный | AB7: зеленый | AC7: серый | AD7: желтый | AE7: желтый | AF7: желтый | AG7: фиолетовый | AL7: =IF($BK$3=E7,1,IF($BK$3=F7,2,IF($BK$3=G7,3,IF($BK$3=H7,4,IF($BK$3=I7,5,IF($BK$3=J7,6,IF($BK$3=K7,7,IF($BK$3=L7,8,"")))))))) -> 8 | AM7: =IF($BK$4=E7,1,IF($BK$4=F7,2,IF($BK$4=G7,3,IF($BK$4=H7,4,IF($BK$4=I7,5,IF($BK$4=J7,6,IF($BK$4=K7,7,IF($BK$4=L7,8,"")))))))) -> 1 | AN7: =IF($BK$5=E7,1, IF($BK$5=F7,2, IF($BK$5=G7,3,IF($BK$5=H7,4, IF($BK$5=I7,5, IF($BK$5=J7,6, IF($BK$5=K7,7, IF($BK$5=L7,8,"")))))))) -> 4 | AO7: =IF($BK$9=E7,1, IF($BK$9=F7,2, IF($BK$9=G7,3,IF($BK$9=H7,4, IF($BK$9=I7,5, IF($BK$9=J7,6, IF($BK$9=K7,7,IF($BK$9=L7,8,"")))))))) -> 6 | AP7: =IF($BK$6=E7,1,IF($BK$6=F7,2,IF($BK$6=G7,3,IF($BK$6=H7,4,IF($BK$6=I7,5,IF($BK$6=J7,6,IF($BK$6=K7,7,IF($BK$6=L7,8,"")))))))) -> 3 | AQ7: =IF($BK$7=E7,1,IF($BK$7=F7,2,IF($BK$7=G7,3,IF($BK$7=H7,4,IF($BK$7=I7,5,IF($BK$7=J7,6,IF($BK$7=K7,7,IF($BK$7=L7,8,"")))))))) -> 7 | AR7: =IF($BK$8=E7,1, IF($BK$8=F7,2, IF($BK$8=G7,3,IF($BK$8=H7,4, IF($BK$8=I7,5, IF($BK$8=J7,6, IF($BK$8=K7,7,IF($BK$8=L7,8,"")))))))) -> 5 | AS7: =IF($BK$10=E7,1, IF($BK$10=F7,2, IF($BK$10=G7,3,IF($BK$10=H7,4, IF($BK$10=I7,5, IF($BK$10=J7,6, IF($BK$10=K7,7, IF($BK$10=L7,8,"")))))))) -> 2 | AT7: =IF(AM7="","",AM7) -> 1 | AU7: =IF(AN7="","",AN7) -> 4 | AV7: =IF(AP7="","",AP7) -> 3 | AW7: =IF(AQ7="","",AQ7) -> 7 | AX7: =IF(AL7="","",AL7) -> 8 | AY7: =IF(AO7="","",AO7) -> 6 | AZ7: =IF(AR7="","",AR7) -> 5 | BA7: =IF(AS7="","",AS7) -> 2 | BB7: =IF(AT7="","",ABS(AT7-1)) -> 0 | BC7: =IF(AU7="","",ABS(AU7-2)) -> 2 | BD7: =IF(AV7="","",ABS(AV7-3)) -> 0 | BE7: =IF(AW7="","",ABS(AW7-4)) -> 3 | BF7: =IF(AX7="","",ABS(AX7-5)) -> 3 | BG7: =IF(AY7="","",ABS(AY7-6)) -> 0 | BH7: =IF(AZ7="","",ABS(AZ7-7)) -> 2 | BI7: =IF(L7="","",ABS(BA7-8)) -> 6 | BJ7: 5 | BK7: фиолетовый | BL7: 5 | BM7: 4
A8: 6 | B8: Е | C8: 2 а | AL8: =IF($BK$3=E8,1,IF($BK$3=F8,2,IF($BK$3=G8,3,IF($BK$3=H8,4,IF($BK$3=I8,5,IF($BK$3=J8,6,IF($BK$3=K8,7,IF($BK$3=L8,8,"")))))))) | AM8: =IF($BK$4=E8,1,IF($BK$4=F8,2,IF($BK$4=G8,3,IF($BK$4=H8,4,IF($BK$4=I8,5,IF($BK$4=J8,6,IF($BK$4=K8,7,IF($BK$4=L8,8,"")))))))) | AN8: =IF($BK$5=E8,1, IF($BK$5=F8,2, IF($BK$5=G8,3,IF($BK$5=H8,4, IF($BK$5=I8,5, IF($BK$5=J8,6, IF($BK$5=K8,7, IF($BK$5=L8,8,"")))))))) | AO8: =IF($BK$9=E8,1, IF($BK$9=F8,2, IF($BK$9=G8,3,IF($BK$9=H8,4, IF($BK$9=I8,5, IF($BK$9=J8,6, IF($BK$9=K8,7,IF($BK$9=L8,8,"")))))))) | AP8: =IF($BK$6=E8,1,IF($BK$6=F8,2,IF($BK$6=G8,3,IF($BK$6=H8,4,IF($BK$6=I8,5,IF($BK$6=J8,6,IF($BK$6=K8,7,IF($BK$6=L8,8,"")))))))) | AQ8: =IF($BK$7=E8,1,IF($BK$7=F8,2,IF($BK$7=G8,3,IF($BK$7=H8,4,IF($BK$7=I8,5,IF($BK$7=J8,6,IF($BK$7=K8,7,IF($BK$7=L8,8,"")))))))) | AR8: =IF($BK$8=E8,1, IF($BK$8=F8,2, IF($BK$8=G8,3,IF($BK$8=H8,4, IF($BK$8=I8,5, IF($BK$8=J8,6, IF($BK$8=K8,7,IF($BK$8=L8,8,"")))))))) | AS8: =IF($BK$10=E8,1, IF($BK$10=F8,2, IF($BK$10=G8,3,IF($BK$10=H8,4, IF($BK$10=I8,5, IF($BK$10=J8,6, IF($BK$10=K8,7, IF($BK$10=L8,8,"")))))))) | AT8: =IF(AM8="","",AM8) | AU8: =IF(AN8="","",AN8) | AV8: =IF(AP8="","",AP8) | AW8: =IF(AQ8="","",AQ8) | AX8: =IF(AL8="","",AL8) | AY8: =IF(AO8="","",AO8) | AZ8: =IF(AR8="","",AR8) | BA8: =IF(AS8="","",AS8) | BB8: =IF(AT8="","",ABS(AT8-1)) | BC8: =IF(AU8="","",ABS(AU8-2)) | BD8: =IF(AV8="","",ABS(AV8-3)) | BE8: =IF(AW8="","",ABS(AW8-4)) | BF8: =IF(AX8="","",ABS(AX8-5)) | BG8: =IF(AY8="","",ABS(AY8-6)) | BH8: =IF(AZ8="","",ABS(AZ8-7)) | BI8: =IF(L8="","",ABS(BA8-8)) | BJ8: 0 | BK8: серый | BL8: 6 | BM8: 7
A9: 7 | B9: Ж | C9: 2 а | E9: фиолетовый | F9: синий | G9: желтый | H9: красный | I9: черный | J9: зеленый | K9: серый | L9: коричневый | M9: фиолетовый | N9: синий | O9: зеленый | P9: коричневый | Q9: желтый | R9: черный | S9: синий | T9: красный | U9: коричневый | V9: фиолетовый | X9: фиолетовый | Y9: зеленый | Z9: синий | AA9: синий | AB9: синий | AC9: желтый | AD9: желтый | AE9: желтый | AF9: фиолетовый | AG9: коричневый | AH9: желтый | AL9: =IF($BK$3=E9,1,IF($BK$3=F9,2,IF($BK$3=G9,3,IF($BK$3=H9,4,IF($BK$3=I9,5,IF($BK$3=J9,6,IF($BK$3=K9,7,IF($BK$3=L9,8,"")))))))) -> 2 | AM9: =IF($BK$4=E9,1,IF($BK$4=F9,2,IF($BK$4=G9,3,IF($BK$4=H9,4,IF($BK$4=I9,5,IF($BK$4=J9,6,IF($BK$4=K9,7,IF($BK$4=L9,8,"")))))))) -> 4 | AN9: =IF($BK$5=E9,1, IF($BK$5=F9,2, IF($BK$5=G9,3,IF($BK$5=H9,4, IF($BK$5=I9,5, IF($BK$5=J9,6, IF($BK$5=K9,7, IF($BK$5=L9,8,"")))))))) -> 3 | AO9: =IF($BK$9=E9,1, IF($BK$9=F9,2, IF($BK$9=G9,3,IF($BK$9=H9,4, IF($BK$9=I9,5, IF($BK$9=J9,6, IF($BK$9=K9,7,IF($BK$9=L9,8,"")))))))) -> 8 | AP9: =IF($BK$6=E9,1,IF($BK$6=F9,2,IF($BK$6=G9,3,IF($BK$6=H9,4,IF($BK$6=I9,5,IF($BK$6=J9,6,IF($BK$6=K9,7,IF($BK$6=L9,8,"")))))))) -> 6 | AQ9: =IF($BK$7=E9,1,IF($BK$7=F9,2,IF($BK$7=G9,3,IF($BK$7=H9,4,IF($BK$7=I9,5,IF($BK$7=J9,6,IF($BK$7=K9,7,IF($BK$7=L9,8,"")))))))) -> 1 | AR9: =IF($BK$8=E9,1, IF($BK$8=F9,2, IF($BK$8=G9,3,IF($BK$8=H9,4, IF($BK$8=I9,5, IF($BK$8=J9,6, IF($BK$8=K9,7,IF($BK$8=L9,8,"")))))))) -> 7 | AS9: =IF($BK$10=E9,1, IF($BK$10=F9,2, IF($BK$10=G9,3,IF($BK$10=H9,4, IF($BK$10=I9,5, IF($BK$10=J9,6, IF($BK$10=K9,7, IF($BK$10=L9,8,"")))))))) -> 5 | AT9: =IF(AM9="","",AM9) -> 4 | AU9: =IF(AN9="","",AN9) -> 3 | AV9: =IF(AP9="","",AP9) -> 6 | AW9: =IF(AQ9="","",AQ9) -> 1 | AX9: =IF(AL9="","",AL9) -> 2 | AY9: =IF(AO9="","",AO9) -> 8 | AZ9: =IF(AR9="","",AR9) -> 7 | BA9: =IF(AS9="","",AS9) -> 5 | BB9: =IF(AT9="","",ABS(AT9-1)) -> 3 | BC9: =IF(AU9="","",ABS(AU9-2)) -> 1 | BD9: =IF(AV9="","",ABS(AV9-3)) -> 3 | BE9: =IF(AW9="","",ABS(AW9-4)) -> 3 | BF9: =IF(AX9="","",ABS(AX9-5)) -> 3 | BG9: =IF(AY9="","",ABS(AY9-6)) -> 2 | BH9: =IF(AZ9="","",ABS(AZ9-7)) -> 0 | BI9: =IF(L9="","",ABS(BA9-8)) -> 3 | BJ9: 6 | BK9: коричневый | BL9: 7 | BM9: 6
A10: 8 | B10: З | C10: 2 а | E10: синий | F10: коричневый | G10: желтый | H10: фиолетовый | I10: черный | J10: красный | K10: серый | L10: зеленый | M10: синий | N10: коричневый | O10: серый | P10: желтый | Q10: синий | R10: зеленый | S10: красный | T10: коричневый | U10: фиолетовый | V10: красный | X10: синий | Y10: желтый | Z10: красный | AA10: синий | AB10: черный | AC10: синий | AD10: синий | AE10: желтый | AF10: красный | AG10: синий | AH10: синий | AL10: =IF($BK$3=E10,1,IF($BK$3=F10,2,IF($BK$3=G10,3,IF($BK$3=H10,4,IF($BK$3=I10,5,IF($BK$3=J10,6,IF($BK$3=K10,7,IF($BK$3=L10,8,"")))))))) -> 1 | AM10: =IF($BK$4=E10,1,IF($BK$4=F10,2,IF($BK$4=G10,3,IF($BK$4=H10,4,IF($BK$4=I10,5,IF($BK$4=J10,6,IF($BK$4=K10,7,IF($BK$4=L10,8,"")))))))) -> 6 | AN10: =IF($BK$5=E10,1, IF($BK$5=F10,2, IF($BK$5=G10,3,IF($BK$5=H10,4, IF($BK$5=I10,5, IF($BK$5=J10,6, IF($BK$5=K10,7, IF($BK$5=L10,8,"")))))))) -> 3 | AO10: =IF($BK$9=E10,1, IF($BK$9=F10,2, IF($BK$9=G10,3,IF($BK$9=H10,4, IF($BK$9=I10,5, IF($BK$9=J10,6, IF($BK$9=K10,7,IF($BK$9=L10,8,"")))))))) -> 2 | AP10: =IF($BK$6=E10,1,IF($BK$6=F10,2,IF($BK$6=G10,3,IF($BK$6=H10,4,IF($BK$6=I10,5,IF($BK$6=J10,6,IF($BK$6=K10,7,IF($BK$6=L10,8,"")))))))) -> 8 | AQ10: =IF($BK$7=E10,1,IF($BK$7=F10,2,IF($BK$7=G10,3,IF($BK$7=H10,4,IF($BK$7=I10,5,IF($BK$7=J10,6,IF($BK$7=K10,7,IF($BK$7=L10,8,"")))))))) -> 4 | AR10: =IF($BK$8=E10,1, IF($BK$8=F10,2, IF($BK$8=G10,3,IF($BK$8=H10,4, IF($BK$8=I10,5, IF($BK$8=J10,6, IF($BK$8=K10,7,IF($BK$8=L10,8,"")))))))) -> 7 | AS10: =IF($BK$10=E10,1, IF($BK$10=F10,2, IF($BK$10=G10,3,IF($BK$10=H10,4, IF($BK$10=I10,5, IF($BK$10=J10,6, IF($BK$10=K10,7, IF($BK$10=L10,8,"")))))))) -> 5 | AT10: =IF(AM10="","",AM10) -> 6 | AU10: =IF(AN10="","",AN10) -> 3 | AV10: =IF(AP10="","",AP10) -> 8 | AW10: =IF(AQ10="","",AQ10) -> 4 | AX10: =IF(AL10="","",AL10) -> 1 | AY10: =IF(AO10="","",AO10) -> 2 | AZ10: =IF(AR10="","",AR10) -> 7 | BA10: =IF(AS10="","",AS10) -> 5 | BB10: =IF(AT10="","",ABS(AT10-1)) -> 5 | BC10: =IF(AU10="","",ABS(AU10-2)) -> 1 | BD10: =IF(AV10="","",ABS(AV10-3)) -> 5 | BE10: =IF(AW10="","",ABS(AW10-4)) -> 0 | BF10: =IF(AX10="","",ABS(AX10-5)) -> 4 | BG10: =IF(AY10="","",ABS(AY10-6)) -> 4 | BH10: =IF(AZ10="","",ABS(AZ10-7)) -> 0 | BI10: =IF(L10="","",ABS(BA10-8)) -> 3 | BJ10: 7 | BK10: черный | BL10: 8 | BM10: 8
A11: 9 | B11: И | C11: 2 а | E11: синий | F11: зеленый | G11: красный | H11: желтый | I11: коричневый | J11: серый | K11: черный | L11: фиолетовый | M11: желтый | N11: синий | O11: зеленый | P11: черный | Q11: желтый | R11: красный | S11: зеленый | T11: красный | U11: черный | V11: желтый | X11: зеленый | Y11: желтый | Z11: зеленый | AA11: зеленый | AB11: зеленый | AC11: желтый | AD11: желтый | AE11: зеленый | AF11: желтый | AG11: зеленый | AL11: =IF($BK$3=E11,1,IF($BK$3=F11,2,IF($BK$3=G11,3,IF($BK$3=H11,4,IF($BK$3=I11,5,IF($BK$3=J11,6,IF($BK$3=K11,7,IF($BK$3=L11,8,"")))))))) -> 1 | AM11: =IF($BK$4=E11,1,IF($BK$4=F11,2,IF($BK$4=G11,3,IF($BK$4=H11,4,IF($BK$4=I11,5,IF($BK$4=J11,6,IF($BK$4=K11,7,IF($BK$4=L11,8,"")))))))) -> 3 | AN11: =IF($BK$5=E11,1, IF($BK$5=F11,2, IF($BK$5=G11,3,IF($BK$5=H11,4, IF($BK$5=I11,5, IF($BK$5=J11,6, IF($BK$5=K11,7, IF($BK$5=L11,8,"")))))))) -> 4 | AO11: =IF($BK$9=E11,1, IF($BK$9=F11,2, IF($BK$9=G11,3,IF($BK$9=H11,4, IF($BK$9=I11,5, IF($BK$9=J11,6, IF($BK$9=K11,7,IF($BK$9=L11,8,"")))))))) -> 5 | AP11: =IF($BK$6=E11,1,IF($BK$6=F11,2,IF($BK$6=G11,3,IF($BK$6=H11,4,IF($BK$6=I11,5,IF($BK$6=J11,6,IF($BK$6=K11,7,IF($BK$6=L11,8,"")))))))) -> 2 | AQ11: =IF($BK$7=E11,1,IF($BK$7=F11,2,IF($BK$7=G11,3,IF($BK$7=H11,4,IF($BK$7=I11,5,IF($BK$7=J11,6,IF($BK$7=K11,7,IF($BK$7=L11,8,"")))))))) -> 8 | AR11: =IF($BK$8=E11,1, IF($BK$8=F11,2, IF($BK$8=G11,3,IF($BK$8=H11,4, IF($BK$8=I11,5, IF($BK$8=J11,6, IF($BK$8=K11,7,IF($BK$8=L11,8,"")))))))) -> 6 | AS11: =IF($BK$10=E11,1, IF($BK$10=F11,2, IF($BK$10=G11,3,IF($BK$10=H11,4, IF($BK$10=I11,5, IF($BK$10=J11,6, IF($BK$10=K11,7, IF($BK$10=L11,8,"")))))))) -> 7 | AT11: =IF(AM11="","",AM11) -> 3 | AU11: =IF(AN11="","",AN11) -> 4 | AV11: =IF(AP11="","",AP11) -> 2 | AW11: =IF(AQ11="","",AQ11) -> 8 | AX11: =IF(AL11="","",AL11) -> 1 | AY11: =IF(AO11="","",AO11) -> 5 | AZ11: =IF(AR11="","",AR11) -> 6 | BA11: =IF(AS11="","",AS11) -> 7 | BB11: =IF(AT11="","",ABS(AT11-1)) -> 2 | BC11: =IF(AU11="","",ABS(AU11-2)) -> 2 | BD11: =IF(AV11="","",ABS(AV11-3)) -> 1 | BE11: =IF(AW11="","",ABS(AW11-4)) -> 4 | BF11: =IF(AX11="","",ABS(AX11-5)) -> 4 | BG11: =IF(AY11="","",ABS(AY11-6)) -> 1 | BH11: =IF(AZ11="","",ABS(AZ11-7)) -> 1 | BI11: =IF(L11="","",ABS(BA11-8)) -> 1
A12: 10 | B12: К | C12: 2 а | E12: синий | F12: желтый | G12: фиолетовый | H12: черный | I12: зеленый | J12: красный | K12: коричневый | L12: серый | M12: желтый | N12: коричневый | O12: красный | P12: серый | Q12: синий | R12: серый | S12: фиолетовый | T12: серый | U12: зеленый | V12: черный | X12: серый | Y12: зеленый | Z12: фиолетовый | AA12: черный | AB12: красный | AC12: синий | AD12: желтый | AE12: синий | AF12: желтый | AG12: черный | AH12: черный | AL12: =IF($BK$3=E12,1,IF($BK$3=F12,2,IF($BK$3=G12,3,IF($BK$3=H12,4,IF($BK$3=I12,5,IF($BK$3=J12,6,IF($BK$3=K12,7,IF($BK$3=L12,8,"")))))))) -> 1 | AM12: =IF($BK$4=E12,1,IF($BK$4=F12,2,IF($BK$4=G12,3,IF($BK$4=H12,4,IF($BK$4=I12,5,IF($BK$4=J12,6,IF($BK$4=K12,7,IF($BK$4=L12,8,"")))))))) -> 6 | AN12: =IF($BK$5=E12,1, IF($BK$5=F12,2, IF($BK$5=G12,3,IF($BK$5=H12,4, IF($BK$5=I12,5, IF($BK$5=J12,6, IF($BK$5=K12,7, IF($BK$5=L12,8,"")))))))) -> 2 | AO12: =IF($BK$9=E12,1, IF($BK$9=F12,2, IF($BK$9=G12,3,IF($BK$9=H12,4, IF($BK$9=I12,5, IF($BK$9=J12,6, IF($BK$9=K12,7,IF($BK$9=L12,8,"")))))))) -> 7 | AP12: =IF($BK$6=E12,1,IF($BK$6=F12,2,IF($BK$6=G12,3,IF($BK$6=H12,4,IF($BK$6=I12,5,IF($BK$6=J12,6,IF($BK$6=K12,7,IF($BK$6=L12,8,"")))))))) -> 5 | AQ12: =IF($BK$7=E12,1,IF($BK$7=F12,2,IF($BK$7=G12,3,IF($BK$7=H12,4,IF($BK$7=I12,5,IF($BK$7=J12,6,IF($BK$7=K12,7,IF($BK$7=L12,8,"")))))))) -> 3 | AR12: =IF($BK$8=E12,1, IF($BK$8=F12,2, IF($BK$8=G12,3,IF($BK$8=H12,4, IF($BK$8=I12,5, IF($BK$8=J12,6, IF($BK$8=K12,7,IF($BK$8=L12,8,"")))))))) -> 8 | AS12: =IF($BK$10=E12,1, IF($BK$10=F12,2, IF($BK$10=G12,3,IF($BK$10=H12,4, IF($BK$10=I12,5, IF($BK$10=J12,6, IF($BK$10=K12,7, IF($BK$10=L12,8,"")))))))) -> 4 | AT12: =IF(AM12="","",AM12) -> 6 | AU12: =IF(AN12="","",AN12) -> 2 | AV12: =IF(AP12="","",AP12) -> 5 | AW12: =IF(AQ12="","",AQ12) -> 3 | AX12: =IF(AL12="","",AL12) -> 1 | AY12: =IF(AO12="","",AO12) -> 7 | AZ12: =IF(AR12="","",AR12) -> 8 | BA12: =IF(AS12="","",AS12) -> 4 | BB12: =IF(AT12="","",ABS(AT12-1)) -> 5 | BC12: =IF(AU12="","",ABS(AU12-2)) -> 0 | BD12: =IF(AV12="","",ABS(AV12-3)) -> 2 | BE12: =IF(AW12="","",ABS(AW12-4)) -> 1 | BF12: =IF(AX12="","",ABS(AX12-5)) -> 4 | BG12: =IF(AY12="","",ABS(AY12-6)) -> 1 | BH12: =IF(AZ12="","",ABS(AZ12-7)) -> 1 | BI12: =IF(L12="","",ABS(BA12-8)) -> 4
A13: 11 | B13: Л | C13: 2 а | E13: зеленый | F13: фиолетовый | G13: синий | H13: серый | I13: черный | J13: красный | K13: коричневый | L13: желтый | M13: синий | N13: коричневый | O13: фиолетовый | P13: черный | Q13: синий | R13: зеленый | S13: желтый | T13: красный | U13: серый | V13: желтый | X13: коричневый | Y13: желтый | Z13: синий | AA13: красный | AB13: серый | AC13: фиолетовый | AD13: синий | AE13: коричневый | AF13: синий | AG13: красный | AH13: синий | AL13: =IF($BK$3=E13,1,IF($BK$3=F13,2,IF($BK$3=G13,3,IF($BK$3=H13,4,IF($BK$3=I13,5,IF($BK$3=J13,6,IF($BK$3=K13,7,IF($BK$3=L13,8,"")))))))) -> 3 | AM13: =IF($BK$4=E13,1,IF($BK$4=F13,2,IF($BK$4=G13,3,IF($BK$4=H13,4,IF($BK$4=I13,5,IF($BK$4=J13,6,IF($BK$4=K13,7,IF($BK$4=L13,8,"")))))))) -> 6 | AN13: =IF($BK$5=E13,1, IF($BK$5=F13,2, IF($BK$5=G13,3,IF($BK$5=H13,4, IF($BK$5=I13,5, IF($BK$5=J13,6, IF($BK$5=K13,7, IF($BK$5=L13,8,"")))))))) -> 8 | AO13: =IF($BK$9=E13,1, IF($BK$9=F13,2, IF($BK$9=G13,3,IF($BK$9=H13,4, IF($BK$9=I13,5, IF($BK$9=J13,6, IF($BK$9=K13,7,IF($BK$9=L13,8,"")))))))) -> 7 | AP13: =IF($BK$6=E13,1,IF($BK$6=F13,2,IF($BK$6=G13,3,IF($BK$6=H13,4,IF($BK$6=I13,5,IF($BK$6=J13,6,IF($BK$6=K13,7,IF($BK$6=L13,8,"")))))))) -> 1 | AQ13: =IF($BK$7=E13,1,IF($BK$7=F13,2,IF($BK$7=G13,3,IF($BK$7=H13,4,IF($BK$7=I13,5,IF($BK$7=J13,6,IF($BK$7=K13,7,IF($BK$7=L13,8,"")))))))) -> 2 | AR13: =IF($BK$8=E13,1, IF($BK$8=F13,2, IF($BK$8=G13,3,IF($BK$8=H13,4, IF($BK$8=I13,5, IF($BK$8=J13,6, IF($BK$8=K13,7,IF($BK$8=L13,8,"")))))))) -> 4 | AS13: =IF($BK$10=E13,1, IF($BK$10=F13,2, IF($BK$10=G13,3,IF($BK$10=H13,4, IF($BK$10=I13,5, IF($BK$10=J13,6, IF($BK$10=K13,7, IF($BK$10=L13,8,"")))))))) -> 5 | AT13: =IF(AM13="","",AM13) -> 6 | AU13: =IF(AN13="","",AN13) -> 8 | AV13: =IF(AP13="","",AP13) -> 1 | AW13: =IF(AQ13="","",AQ13) -> 2 | AX13: =IF(AL13="","",AL13) -> 3 | AY13: =IF(AO13="","",AO13) -> 7 | AZ13: =IF(AR13="","",AR13) -> 4 | BA13: =IF(AS13="","",AS13) -> 5 | BB13: =IF(AT13="","",ABS(AT13-1)) -> 5 | BC13: =IF(AU13="","",ABS(AU13-2)) -> 6 | BD13: =IF(AV13="","",ABS(AV13-3)) -> 2 | BE13: =IF(AW13="","",ABS(AW13-4)) -> 2 | BF13: =IF(AX13="","",ABS(AX13-5)) -> 2 | BG13: =IF(AY13="","",ABS(AY13-6)) -> 1 | BH13: =IF(AZ13="","",ABS(AZ13-7)) -> 3 | BI13: =IF(L13="","",ABS(BA13-8)) -> 3
A14: 12 | B14: М | C14: 2 а | E14: черный | F14: красный | G14: фиолетовый | H14: серый | I14: желтый | J14: зеленый | K14: синий | L14: коричневый | M14: желтый | N14: синий | O14: черный | P14: серый | Q14: зеленый | R14: фиолетовый | S14: желтый | T14: красный | U14: серый | V14: желтый | X14: черный | Y14: красный | Z14: синий | AA14: фиолетовый | AB14: коричневый | AC14: желтый | AD14: желтый | AE14: желтый | AF14: черный | AG14: черный | AH14: черный | AL14: =IF($BK$3=E14,1,IF($BK$3=F14,2,IF($BK$3=G14,3,IF($BK$3=H14,4,IF($BK$3=I14,5,IF($BK$3=J14,6,IF($BK$3=K14,7,IF($BK$3=L14,8,"")))))))) -> 7 | AM14: =IF($BK$4=E14,1,IF($BK$4=F14,2,IF($BK$4=G14,3,IF($BK$4=H14,4,IF($BK$4=I14,5,IF($BK$4=J14,6,IF($BK$4=K14,7,IF($BK$4=L14,8,"")))))))) -> 2 | AN14: =IF($BK$5=E14,1, IF($BK$5=F14,2, IF($BK$5=G14,3,IF($BK$5=H14,4, IF($BK$5=I14,5, IF($BK$5=J14,6, IF($BK$5=K14,7, IF($BK$5=L14,8,"")))))))) -> 5 | AO14: =IF($BK$9=E14,1, IF($BK$9=F14,2, IF($BK$9=G14,3,IF($BK$9=H14,4, IF($BK$9=I14,5, IF($BK$9=J14,6, IF($BK$9=K14,7,IF($BK$9=L14,8,"")))))))) -> 8 | AP14: =IF($BK$6=E14,1,IF($BK$6=F14,2,IF($BK$6=G14,3,IF($BK$6=H14,4,IF($BK$6=I14,5,IF($BK$6=J14,6,IF($BK$6=K14,7,IF($BK$6=L14,8,"")))))))) -> 6 | AQ14: =IF($BK$7=E14,1,IF($BK$7=F14,2,IF($BK$7=G14,3,IF($BK$7=H14,4,IF($BK$7=I14,5,IF($BK$7=J14,6,IF($BK$7=K14,7,IF($BK$7=L14,8,"")))))))) -> 3 | AR14: =IF($BK$8=E14,1, IF($BK$8=F14,2, IF($BK$8=G14,3,IF($BK$8=H14,4, IF($BK$8=I14,5, IF($BK$8=J14,6, IF($BK$8=K14,7,IF($BK$8=L14,8,"")))))))) -> 4 | AS14: =IF($BK$10=E14,1, IF($BK$10=F14,2, IF($BK$10=G14,3,IF($BK$10=H14,4, IF($BK$10=I14,5, IF($BK$10=J14,6, IF($BK$10=K14,7, IF($BK$10=L14,8,"")))))))) -> 1 | AT14: =IF(AM14="","",AM14) -> 2 | AU14: =IF(AN14="","",AN14) -> 5 | AV14: =IF(AP14="","",AP14) -> 6 | AW14: =IF(AQ14="","",AQ14) -> 3 | AX14: =IF(AL14="","",AL14) -> 7 | AY14: =IF(AO14="","",AO14) -> 8 | AZ14: =IF(AR14="","",AR14) -> 4 | BA14: =IF(AS14="","",AS14) -> 1 | BB14: =IF(AT14="","",ABS(AT14-1)) -> 1 | BC14: =IF(AU14="","",ABS(AU14-2)) -> 3 | BD14: =IF(AV14="","",ABS(AV14-3)) -> 3 | BE14: =IF(AW14="","",ABS(AW14-4)) -> 1 | BF14: =IF(AX14="","",ABS(AX14-5)) -> 2 | BG14: =IF(AY14="","",ABS(AY14-6)) -> 2 | BH14: =IF(AZ14="","",ABS(AZ14-7)) -> 3 | BI14: =IF(L14="","",ABS(BA14-8)) -> 7
A15: 13 | B15: Н | C15: 2 а | E15: синий | F15: фиолетовый | G15: желтый | H15: зеленый | I15: черный | J15: красный | K15: серый | L15: коричневый | M15: желтый | N15: черный | O15: синий | P15: зеленый | Q15: желтый | R15: фиолетовый | S15: красный | T15: красный | U15: черный | V15: синий | X15: черный | Y15: красный | Z15: синий | AA15: желтый | AB15: черный | AC15: красный | AD15: фиолетовый | AE15: синий | AF15: синий | AG15: черный | AH15: фиолетовый | AL15: =IF($BK$3=E15,1,IF($BK$3=F15,2,IF($BK$3=G15,3,IF($BK$3=H15,4,IF($BK$3=I15,5,IF($BK$3=J15,6,IF($BK$3=K15,7,IF($BK$3=L15,8,"")))))))) -> 1 | AM15: =IF($BK$4=E15,1,IF($BK$4=F15,2,IF($BK$4=G15,3,IF($BK$4=H15,4,IF($BK$4=I15,5,IF($BK$4=J15,6,IF($BK$4=K15,7,IF($BK$4=L15,8,"")))))))) -> 6 | AN15: =IF($BK$5=E15,1, IF($BK$5=F15,2, IF($BK$5=G15,3,IF($BK$5=H15,4, IF($BK$5=I15,5, IF($BK$5=J15,6, IF($BK$5=K15,7, IF($BK$5=L15,8,"")))))))) -> 3 | AO15: =IF($BK$9=E15,1, IF($BK$9=F15,2, IF($BK$9=G15,3,IF($BK$9=H15,4, IF($BK$9=I15,5, IF($BK$9=J15,6, IF($BK$9=K15,7,IF($BK$9=L15,8,"")))))))) -> 8 | AP15: =IF($BK$6=E15,1,IF($BK$6=F15,2,IF($BK$6=G15,3,IF($BK$6=H15,4,IF($BK$6=I15,5,IF($BK$6=J15,6,IF($BK$6=K15,7,IF($BK$6=L15,8,"")))))))) -> 4 | AQ15: =IF($BK$7=E15,1,IF($BK$7=F15,2,IF($BK$7=G15,3,IF($BK$7=H15,4,IF($BK$7=I15,5,IF($BK$7=J15,6,IF($BK$7=K15,7,IF($BK$7=L15,8,"")))))))) -> 2 | AR15: =IF($BK$8=E15,1, IF($BK$8=F15,2, IF($BK$8=G15,3,IF($BK$8=H15,4, IF($BK$8=I15,5, IF($BK$8=J15,6, IF($BK$8=K15,7,IF($BK$8=L15,8,"")))))))) -> 7 | AS15: =IF($BK$10=E15,1, IF($BK$10=F15,2, IF($BK$10=G15,3,IF($BK$10=H15,4, IF($BK$10=I15,5, IF($BK$10=J15,6, IF($BK$10=K15,7, IF($BK$10=L15,8,"")))))))) -> 5 | AT15: =IF(AM15="","",AM15) -> 6 | AU15: =IF(AN15="","",AN15) -> 3 | AV15: =IF(AP15="","",AP15) -> 4 | AW15: =IF(AQ15="","",AQ15) -> 2 | AX15: =IF(AL15="","",AL15) -> 1 | AY15: =IF(AO15="","",AO15) -> 8 | AZ15: =IF(AR15="","",AR15) -> 7 | BA15: =IF(AS15="","",AS15) -> 5 | BB15: =IF(AT15="","",ABS(AT15-1)) -> 5 | BC15: =IF(AU15="","",ABS(AU15-2)) -> 1 | BD15: =IF(AV15="","",ABS(AV15-3)) -> 1 | BE15: =IF(AW15="","",ABS(AW15-4)) -> 2 | BF15: =IF(AX15="","",ABS(AX15-5)) -> 4 | BG15: =IF(AY15="","",ABS(AY15-6)) -> 2 | BH15: =IF(AZ15="","",ABS(AZ15-7)) -> 0 | BI15: =IF(L15="","",ABS(BA15-8)) -> 3
A16: 14 | B16: О | C16: 2 а | E16: синий | F16: зеленый | G16: фиолетовый | H16: красный | I16: желтый | J16: черный | K16: серый | L16: коричневый | M16: синий | N16: серый | O16: фиолетовый | P16: черный | Q16: зеленый | R16: красный | S16: синий | T16: коричневый | U16: желтый | V16: синий | X16: серый | Y16: фиолетовый | Z16: зеленый | AA16: синий | AB16: коричневый | AC16: синий | AD16: красный | AE16: синий | AF16: синий | AG16: коричневый | AH16: синий | AL16: =IF($BK$3=E16,1,IF($BK$3=F16,2,IF($BK$3=G16,3,IF($BK$3=H16,4,IF($BK$3=I16,5,IF($BK$3=J16,6,IF($BK$3=K16,7,IF($BK$3=L16,8,"")))))))) -> 1 | AM16: =IF($BK$4=E16,1,IF($BK$4=F16,2,IF($BK$4=G16,3,IF($BK$4=H16,4,IF($BK$4=I16,5,IF($BK$4=J16,6,IF($BK$4=K16,7,IF($BK$4=L16,8,"")))))))) -> 4 | AN16: =IF($BK$5=E16,1, IF($BK$5=F16,2, IF($BK$5=G16,3,IF($BK$5=H16,4, IF($BK$5=I16,5, IF($BK$5=J16,6, IF($BK$5=K16,7, IF($BK$5=L16,8,"")))))))) -> 5 | AO16: =IF($BK$9=E16,1, IF($BK$9=F16,2, IF($BK$9=G16,3,IF($BK$9=H16,4, IF($BK$9=I16,5, IF($BK$9=J16,6, IF($BK$9=K16,7,IF($BK$9=L16,8,"")))))))) -> 8 | AP16: =IF($BK$6=E16,1,IF($BK$6=F16,2,IF($BK$6=G16,3,IF($BK$6=H16,4,IF($BK$6=I16,5,IF($BK$6=J16,6,IF($BK$6=K16,7,IF($BK$6=L16,8,"")))))))) -> 2 | AQ16: =IF($BK$7=E16,1,IF($BK$7=F16,2,IF($BK$7=G16,3,IF($BK$7=H16,4,IF($BK$7=I16,5,IF($BK$7=J16,6,IF($BK$7=K16,7,IF($BK$7=L16,8,"")))))))) -> 3 | AR16: =IF($BK$8=E16,1, IF($BK$8=F16,2, IF($BK$8=G16,3,IF($BK$8=H16,4, IF($BK$8=I16,5, IF($BK$8=J16,6, IF($BK$8=K16,7,IF($BK$8=L16,8,"")))))))) -> 7 | AS16: =IF($BK$10=E16,1, IF($BK$10=F16,2, IF($BK$10=G16,3,IF($BK$10=H16,4, IF($BK$10=I16,5, IF($BK$10=J16,6, IF($BK$10=K16,7, IF($BK$10=L16,8,"")))))))) -> 6 | AT16: =IF(AM16="","",AM16) -> 4 | AU16: =IF(AN16="","",AN16) -> 5 | AV16: =IF(AP16="","",AP16) -> 2 | AW16: =IF(AQ16="","",AQ16) -> 3 | AX16: =IF(AL16="","",AL16) -> 1 | AY16: =IF(AO16="","",AO16) -> 8 | AZ16: =IF(AR16="","",AR16) -> 7 | BA16: =IF(AS16="","",AS16) -> 6 | BB16: =IF(AT16="","",ABS(AT16-1)) -> 3 | BC16: =IF(AU16="","",ABS(AU16-2)) -> 3 | BD16: =IF(AV16="","",ABS(AV16-3)) -> 1 | BE16: =IF(AW16="","",ABS(AW16-4)) -> 1 | BF16: =IF(AX16="","",ABS(AX16-5)) -> 4 | BG16: =IF(AY16="","",ABS(AY16-6)) -> 2 | BH16: =IF(AZ16="","",ABS(AZ16-7)) -> 0 | BI16: =IF(L16="","",ABS(BA16-8)) -> 2
A17: 15 | B17: П | C17: 2 а | E17: синий | F17: желтый | G17: красный | H17: фиолетовый | I17: серый | J17: зеленый | K17: черный | L17: коричневый | M17: желтый | N17: коричневый | O17: фиолетовый | P17: черный | Q17: синий | R17: черный | S17: красный | T17: зеленый | U17: фиолетовый | V17: желтый | X17: черный | Y17: зеленый | Z17: синий | AA17: коричневый | AB17: черный | AC17: красный | AD17: желтый | AE17: синий | AF17: синий | AG17: черный | AH17: желтый | AL17: =IF($BK$3=E17,1,IF($BK$3=F17,2,IF($BK$3=G17,3,IF($BK$3=H17,4,IF($BK$3=I17,5,IF($BK$3=J17,6,IF($BK$3=K17,7,IF($BK$3=L17,8,"")))))))) -> 1 | AM17: =IF($BK$4=E17,1,IF($BK$4=F17,2,IF($BK$4=G17,3,IF($BK$4=H17,4,IF($BK$4=I17,5,IF($BK$4=J17,6,IF($BK$4=K17,7,IF($BK$4=L17,8,"")))))))) -> 3 | AN17: =IF($BK$5=E17,1, IF($BK$5=F17,2, IF($BK$5=G17,3,IF($BK$5=H17,4, IF($BK$5=I17,5, IF($BK$5=J17,6, IF($BK$5=K17,7, IF($BK$5=L17,8,"")))))))) -> 2 | AO17: =IF($BK$9=E17,1, IF($BK$9=F17,2, IF($BK$9=G17,3,IF($BK$9=H17,4, IF($BK$9=I17,5, IF($BK$9=J17,6, IF($BK$9=K17,7,IF($BK$9=L17,8,"")))))))) -> 8 | AP17: =IF($BK$6=E17,1,IF($BK$6=F17,2,IF($BK$6=G17,3,IF($BK$6=H17,4,IF($BK$6=I17,5,IF($BK$6=J17,6,IF($BK$6=K17,7,IF($BK$6=L17,8,"")))))))) -> 6 | AQ17: =IF($BK$7=E17,1,IF($BK$7=F17,2,IF($BK$7=G17,3,IF($BK$7=H17,4,IF($BK$7=I17,5,IF($BK$7=J17,6,IF($BK$7=K17,7,IF($BK$7=L17,8,"")))))))) -> 4 | AR17: =IF($BK$8=E17,1, IF($BK$8=F17,2, IF($BK$8=G17,3,IF($BK$8=H17,4, IF($BK$8=I17,5, IF($BK$8=J17,6, IF($BK$8=K17,7,IF($BK$8=L17,8,"")))))))) -> 5 | AS17: =IF($BK$10=E17,1, IF($BK$10=F17,2, IF($BK$10=G17,3,IF($BK$10=H17,4, IF($BK$10=I17,5, IF($BK$10=J17,6, IF($BK$10=K17,7, IF($BK$10=L17,8,"")))))))) -> 7 | AT17: =IF(AM17="","",AM17) -> 3 | AU17: =IF(AN17="","",AN17) -> 2 | AV17: =IF(AP17="","",AP17) -> 6 | AW17: =IF(AQ17="","",AQ17) -> 4 | AX17: =IF(AL17="","",AL17) -> 1 | AY17: =IF(AO17="","",AO17) -> 8 | AZ17: =IF(AR17="","",AR17) -> 5 | BA17: =IF(AS17="","",AS17) -> 7 | BB17: =IF(AT17="","",ABS(AT17-1)) -> 2 | BC17: =IF(AU17="","",ABS(AU17-2)) -> 0 | BD17: =IF(AV17="","",ABS(AV17-3)) -> 3 | BE17: =IF(AW17="","",ABS(AW17-4)) -> 0 | BF17: =IF(AX17="","",ABS(AX17-5)) -> 4 | BG17: =IF(AY17="","",ABS(AY17-6)) -> 2 | BH17: =IF(AZ17="","",ABS(AZ17-7)) -> 2 | BI17: =IF(L17="","",ABS(BA17-8)) -> 1
A18: 16 | B18: Р | C18: 2 а | E18: красный | F18: зеленый | G18: синий | H18: фиолетовый | I18: коричневый | J18: черный | K18: серый | L18: желтый | M18: фиолетовый | N18: синий | O18: черный | P18: желтый | Q18: зеленый | R18: серый | S18: красный | T18: черный | U18: фиолетовый | V18: черный | X18: черный | Y18: черный | Z18: фиолетовый | AA18: черный | AB18: черный | AC18: черный | AD18: коричневый | AE18: фиолетовый | AF18: черный | AG18: черный | AH18: красный | AL18: =IF($BK$3=E18,1,IF($BK$3=F18,2,IF($BK$3=G18,3,IF($BK$3=H18,4,IF($BK$3=I18,5,IF($BK$3=J18,6,IF($BK$3=K18,7,IF($BK$3=L18,8,"")))))))) -> 3 | AM18: =IF($BK$4=E18,1,IF($BK$4=F18,2,IF($BK$4=G18,3,IF($BK$4=H18,4,IF($BK$4=I18,5,IF($BK$4=J18,6,IF($BK$4=K18,7,IF($BK$4=L18,8,"")))))))) -> 1 | AN18: =IF($BK$5=E18,1, IF($BK$5=F18,2, IF($BK$5=G18,3,IF($BK$5=H18,4, IF($BK$5=I18,5, IF($BK$5=J18,6, IF($BK$5=K18,7, IF($BK$5=L18,8,"")))))))) -> 8 | AO18: =IF($BK$9=E18,1, IF($BK$9=F18,2, IF($BK$9=G18,3,IF($BK$9=H18,4, IF($BK$9=I18,5, IF($BK$9=J18,6, IF($BK$9=K18,7,IF($BK$9=L18,8,"")))))))) -> 5 | AP18: =IF($BK$6=E18,1,IF($BK$6=F18,2,IF($BK$6=G18,3,IF($BK$6=H18,4,IF($BK$6=I18,5,IF($BK$6=J18,6,IF($BK$6=K18,7,IF($BK$6=L18,8,"")))))))) -> 2 | AQ18: =IF($BK$7=E18,1,IF($BK$7=F18,2,IF($BK$7=G18,3,IF($BK$7=H18,4,IF($BK$7=I18,5,IF($BK$7=J18,6,IF($BK$7=K18,7,IF($BK$7=L18,8,"")))))))) -> 4 | AR18: =IF($BK$8=E18,1, IF($BK$8=F18,2, IF($BK$8=G18,3,IF($BK$8=H18,4, IF($BK$8=I18,5, IF($BK$8=J18,6, IF($BK$8=K18,7,IF($BK$8=L18,8,"")))))))) -> 7 | AS18: =IF($BK$10=E18,1, IF($BK$10=F18,2, IF($BK$10=G18,3,IF($BK$10=H18,4, IF($BK$10=I18,5, IF($BK$10=J18,6, IF($BK$10=K18,7, IF($BK$10=L18,8,"")))))))) -> 6 | AT18: =IF(AM18="","",AM18) -> 1 | AU18: =IF(AN18="","",AN18) -> 8 | AV18: =IF(AP18="","",AP18) -> 2 | AW18: =IF(AQ18="","",AQ18) -> 4 | AX18: =IF(AL18="","",AL18) -> 3 | AY18: =IF(AO18="","",AO18) -> 5 | AZ18: =IF(AR18="","",AR18) -> 7 | BA18: =IF(AS18="","",AS18) -> 6 | BB18: =IF(AT18="","",ABS(AT18-1)) -> 0 | BC18: =IF(AU18="","",ABS(AU18-2)) -> 6 | BD18: =IF(AV18="","",ABS(AV18-3)) -> 1 | BE18: =IF(AW18="","",ABS(AW18-4)) -> 0 | BF18: =IF(AX18="","",ABS(AX18-5)) -> 2 | BG18: =IF(AY18="","",ABS(AY18-6)) -> 1 | BH18: =IF(AZ18="","",ABS(AZ18-7)) -> 0 | BI18: =IF(L18="","",ABS(BA18-8)) -> 2
A19: 17 | B19: С | C19: 2 а | E19: красный | F19: зеленый | G19: синий | H19: черный | I19: серый | J19: желтый | K19: фиолетовый | L19: коричневый | M19: синий | N19: черный | O19: серый | P19: фиолетовый | Q19: зеленый | R19: коричневый | S19: фиолетовый | T19: черный | U19: серый | V19: красный | X19: фиолетовый | Y19: серый | Z19: коричневый | AA19: черный | AB19: коричневый | AC19: желтый | AD19: синий | AE19: зеленый | AF19: зеленый | AG19: коричневый | AH19: красный | AL19: =IF($BK$3=E19,1,IF($BK$3=F19,2,IF($BK$3=G19,3,IF($BK$3=H19,4,IF($BK$3=I19,5,IF($BK$3=J19,6,IF($BK$3=K19,7,IF($BK$3=L19,8,"")))))))) -> 3 | AM19: =IF($BK$4=E19,1,IF($BK$4=F19,2,IF($BK$4=G19,3,IF($BK$4=H19,4,IF($BK$4=I19,5,IF($BK$4=J19,6,IF($BK$4=K19,7,IF($BK$4=L19,8,"")))))))) -> 1 | AN19: =IF($BK$5=E19,1, IF($BK$5=F19,2, IF($BK$5=G19,3,IF($BK$5=H19,4, IF($BK$5=I19,5, IF($BK$5=J19,6, IF($BK$5=K19,7, IF($BK$5=L19,8,"")))))))) -> 6 | AO19: =IF($BK$9=E19,1, IF($BK$9=F19,2, IF($BK$9=G19,3,IF($BK$9=H19,4, IF($BK$9=I19,5, IF($BK$9=J19,6, IF($BK$9=K19,7,IF($BK$9=L19,8,"")))))))) -> 8 | AP19: =IF($BK$6=E19,1,IF($BK$6=F19,2,IF($BK$6=G19,3,IF($BK$6=H19,4,IF($BK$6=I19,5,IF($BK$6=J19,6,IF($BK$6=K19,7,IF($BK$6=L19,8,"")))))))) -> 2 | AQ19: =IF($BK$7=E19,1,IF($BK$7=F19,2,IF($BK$7=G19,3,IF($BK$7=H19,4,IF($BK$7=I19,5,IF($BK$7=J19,6,IF($BK$7=K19,7,IF($BK$7=L19,8,"")))))))) -> 7 | AR19: =IF($BK$8=E19,1, IF($BK$8=F19,2, IF($BK$8=G19,3,IF($BK$8=H19,4, IF($BK$8=I19,5, IF($BK$8=J19,6, IF($BK$8=K19,7,IF($BK$8=L19,8,"")))))))) -> 5 | AS19: =IF($BK$10=E19,1, IF($BK$10=F19,2, IF($BK$10=G19,3,IF($BK$10=H19,4, IF($BK$10=I19,5, IF($BK$10=J19,6, IF($BK$10=K19,7, IF($BK$10=L19,8,"")))))))) -> 4 | AT19: =IF(AM19="","",AM19) -> 1 | AU19: =IF(AN19="","",AN19) -> 6 | AV19: =IF(AP19="","",AP19) -> 2 | AW19: =IF(AQ19="","",AQ19) -> 7 | AX19: =IF(AL19="","",AL19) -> 3 | AY19: =IF(AO19="","",AO19) -> 8 | AZ19: =IF(AR19="","",AR19) -> 5 | BA19: =IF(AS19="","",AS19) -> 4 | BB19: =IF(AT19="","",ABS(AT19-1)) -> 0 | BC19: =IF(AU19="","",ABS(AU19-2)) -> 4 | BD19: =IF(AV19="","",ABS(AV19-3)) -> 1 | BE19: =IF(AW19="","",ABS(AW19-4)) -> 3 | BF19: =IF(AX19="","",ABS(AX19-5)) -> 2 | BG19: =IF(AY19="","",ABS(AY19-6)) -> 2 | BH19: =IF(AZ19="","",ABS(AZ19-7)) -> 2 | BI19: =IF(L19="","",ABS(BA19-8)) -> 4
A20: 18 | B20: Т | C20: 2 а | E20: красный | F20: черный | G20: желтый | H20: синий | I20: зеленый | J20: серый | K20: фиолетовый | L20: коричневый | M20: желтый | N20: коричневый | O20: синий | P20: фиолетовый | Q20: красный | R20: серый | S20: зеленый | T20: черный | U20: фиолетовый | V20: желтый | X20: фиолетовый | Y20: зеленый | Z20: желтый | AA20: коричневый | AB20: черный | AC20: красный | AD20: желтый | AE20: желтый | AF20: красный | AG20: черный | AH20: желтый | AL20: =IF($BK$3=E20,1,IF($BK$3=F20,2,IF($BK$3=G20,3,IF($BK$3=H20,4,IF($BK$3=I20,5,IF($BK$3=J20,6,IF($BK$3=K20,7,IF($BK$3=L20,8,"")))))))) -> 4 | AM20: =IF($BK$4=E20,1,IF($BK$4=F20,2,IF($BK$4=G20,3,IF($BK$4=H20,4,IF($BK$4=I20,5,IF($BK$4=J20,6,IF($BK$4=K20,7,IF($BK$4=L20,8,"")))))))) -> 1 | AN20: =IF($BK$5=E20,1, IF($BK$5=F20,2, IF($BK$5=G20,3,IF($BK$5=H20,4, IF($BK$5=I20,5, IF($BK$5=J20,6, IF($BK$5=K20,7, IF($BK$5=L20,8,"")))))))) -> 3 | AO20: =IF($BK$9=E20,1, IF($BK$9=F20,2, IF($BK$9=G20,3,IF($BK$9=H20,4, IF($BK$9=I20,5, IF($BK$9=J20,6, IF($BK$9=K20,7,IF($BK$9=L20,8,"")))))))) -> 8 | AP20: =IF($BK$6=E20,1,IF($BK$6=F20,2,IF($BK$6=G20,3,IF($BK$6=H20,4,IF($BK$6=I20,5,IF($BK$6=J20,6,IF($BK$6=K20,7,IF($BK$6=L20,8,"")))))))) -> 5 | AQ20: =IF($BK$7=E20,1,IF($BK$7=F20,2,IF($BK$7=G20,3,IF($BK$7=H20,4,IF($BK$7=I20,5,IF($BK$7=J20,6,IF($BK$7=K20,7,IF($BK$7=L20,8,"")))))))) -> 7 | AR20: =IF($BK$8=E20,1, IF($BK$8=F20,2, IF($BK$8=G20,3,IF($BK$8=H20,4, IF($BK$8=I20,5, IF($BK$8=J20,6, IF($BK$8=K20,7,IF($BK$8=L20,8,"")))))))) -> 6 | AS20: =IF($BK$10=E20,1, IF($BK$10=F20,2, IF($BK$10=G20,3,IF($BK$10=H20,4, IF($BK$10=I20,5, IF($BK$10=J20,6, IF($BK$10=K20,7, IF($BK$10=L20,8,"")))))))) -> 2 | AT20: =IF(AM20="","",AM20) -> 1 | AU20: =IF(AN20="","",AN20) -> 3 | AV20: =IF(AP20="","",AP20) -> 5 | AW20: =IF(AQ20="","",AQ20) -> 7 | AX20: =IF(AL20="","",AL20) -> 4 | AY20: =IF(AO20="","",AO20) -> 8 | AZ20: =IF(AR20="","",AR20) -> 6 | BA20: =IF(AS20="","",AS20) -> 2 | BB20: =IF(AT20="","",ABS(AT20-1)) -> 0 | BC20: =IF(AU20="","",ABS(AU20-2)) -> 1 | BD20: =IF(AV20="","",ABS(AV20-3)) -> 2 | BE20: =IF(AW20="","",ABS(AW20-4)) -> 3 | BF20: =IF(AX20="","",ABS(AX20-5)) -> 1 | BG20: =IF(AY20="","",ABS(AY20-6)) -> 2 | BH20: =IF(AZ20="","",ABS(AZ20-7)) -> 1 | BI20: =IF(L20="","",ABS(BA20-8)) -> 6
A21: 19 | B21: У | C21: 2 а | E21: синий | F21: зеленый | G21: желтый | H21: фиолетовый | I21: серый | J21: черный | K21: красный | L21: коричневый | M21: синий | N21: коричневый | O21: фиолетовый | P21: коричневый | Q21: синий | R21: красный | S21: желтый | T21: коричневый | U21: черный | V21: зеленый | X21: синий | Y21: черный | Z21: синий | AA21: фиолетовый | AB21: черный | AC21: синий | AD21: синий | AE21: синий | AF21: синий | AG21: черный | AH21: синий | AL21: =IF($BK$3=E21,1,IF($BK$3=F21,2,IF($BK$3=G21,3,IF($BK$3=H21,4,IF($BK$3=I21,5,IF($BK$3=J21,6,IF($BK$3=K21,7,IF($BK$3=L21,8,"")))))))) -> 1 | AM21: =IF($BK$4=E21,1,IF($BK$4=F21,2,IF($BK$4=G21,3,IF($BK$4=H21,4,IF($BK$4=I21,5,IF($BK$4=J21,6,IF($BK$4=K21,7,IF($BK$4=L21,8,"")))))))) -> 7 | AN21: =IF($BK$5=E21,1, IF($BK$5=F21,2, IF($BK$5=G21,3,IF($BK$5=H21,4, IF($BK$5=I21,5, IF($BK$5=J21,6, IF($BK$5=K21,7, IF($BK$5=L21,8,"")))))))) -> 3 | AO21: =IF($BK$9=E21,1, IF($BK$9=F21,2, IF($BK$9=G21,3,IF($BK$9=H21,4, IF($BK$9=I21,5, IF($BK$9=J21,6, IF($BK$9=K21,7,IF($BK$9=L21,8,"")))))))) -> 8 | AP21: =IF($BK$6=E21,1,IF($BK$6=F21,2,IF($BK$6=G21,3,IF($BK$6=H21,4,IF($BK$6=I21,5,IF($BK$6=J21,6,IF($BK$6=K21,7,IF($BK$6=L21,8,"")))))))) -> 2 | AQ21: =IF($BK$7=E21,1,IF($BK$7=F21,2,IF($BK$7=G21,3,IF($BK$7=H21,4,IF($BK$7=I21,5,IF($BK$7=J21,6,IF($BK$7=K21,7,IF($BK$7=L21,8,"")))))))) -> 4 | AR21: =IF($BK$8=E21,1, IF($BK$8=F21,2, IF($BK$8=G21,3,IF($BK$8=H21,4, IF($BK$8=I21,5, IF($BK$8=J21,6, IF($BK$8=K21,7,IF($BK$8=L21,8,"")))))))) -> 5 | AS21: =IF($BK$10=E21,1, IF($BK$10=F21,2, IF($BK$10=G21,3,IF($BK$10=H21,4, IF($BK$10=I21,5, IF($BK$10=J21,6, IF($BK$10=K21,7, IF($BK$10=L21,8,"")))))))) -> 6 | AT21: =IF(AM21="","",AM21) -> 7 | AU21: =IF(AN21="","",AN21) -> 3 | AV21: =IF(AP21="","",AP21) -> 2 | AW21: =IF(AQ21="","",AQ21) -> 4 | AX21: =IF(AL21="","",AL21) -> 1 | AY21: =IF(AO21="","",AO21) -> 8 | AZ21: =IF(AR21="","",AR21) -> 5 | BA21: =IF(AS21="","",AS21) -> 6 | BB21: =IF(AT21="","",ABS(AT21-1)) -> 6 | BC21: =IF(AU21="","",ABS(AU21-2)) -> 1 | BD21: =IF(AV21="","",ABS(AV21-3)) -> 1 | BE21: =IF(AW21="","",ABS(AW21-4)) -> 0 | BF21: =IF(AX21="","",ABS(AX21-5)) -> 4 | BG21: =IF(AY21="","",ABS(AY21-6)) -> 2 | BH21: =IF(AZ21="","",ABS(AZ21-7)) -> 2 | BI21: =IF(L21="","",ABS(BA21-8)) -> 2
A22: 20 | B22: Ф | C22: 2 в | E22: синий | F22: фиолетовый | G22: черный | H22: желтый | I22: зеленый | J22: серый | K22: красный | L22: коричневый | M22: желтый | N22: серый | O22: фиолетовый | P22: красный | Q22: синий | R22: черный | S22: зеленый | T22: черный | U22: серый | V22: желтый | X22: серый | Y22: коричневый | Z22: черный | AA22: красный | AB22: черный | AC22: фиолетовый | AD22: синий | AE22: зеленый | AF22: зеленый | AG22: черный | AH22: зеленый | AL22: =IF($BK$3=E22,1,IF($BK$3=F22,2,IF($BK$3=G22,3,IF($BK$3=H22,4,IF($BK$3=I22,5,IF($BK$3=J22,6,IF($BK$3=K22,7,IF($BK$3=L22,8,"")))))))) -> 1 | AM22: =IF($BK$4=E22,1,IF($BK$4=F22,2,IF($BK$4=G22,3,IF($BK$4=H22,4,IF($BK$4=I22,5,IF($BK$4=J22,6,IF($BK$4=K22,7,IF($BK$4=L22,8,"")))))))) -> 7 | AN22: =IF($BK$5=E22,1, IF($BK$5=F22,2, IF($BK$5=G22,3,IF($BK$5=H22,4, IF($BK$5=I22,5, IF($BK$5=J22,6, IF($BK$5=K22,7, IF($BK$5=L22,8,"")))))))) -> 4 | AO22: =IF($BK$9=E22,1, IF($BK$9=F22,2, IF($BK$9=G22,3,IF($BK$9=H22,4, IF($BK$9=I22,5, IF($BK$9=J22,6, IF($BK$9=K22,7,IF($BK$9=L22,8,"")))))))) -> 8 | AP22: =IF($BK$6=E22,1,IF($BK$6=F22,2,IF($BK$6=G22,3,IF($BK$6=H22,4,IF($BK$6=I22,5,IF($BK$6=J22,6,IF($BK$6=K22,7,IF($BK$6=L22,8,"")))))))) -> 5 | AQ22: =IF($BK$7=E22,1,IF($BK$7=F22,2,IF($BK$7=G22,3,IF($BK$7=H22,4,IF($BK$7=I22,5,IF($BK$7=J22,6,IF($BK$7=K22,7,IF($BK$7=L22,8,"")))))))) -> 2 | AR22: =IF($BK$8=E22,1, IF($BK$8=F22,2, IF($BK$8=G22,3,IF($BK$8=H22,4, IF($BK$8=I22,5, IF($BK$8=J22,6, IF($BK$8=K22,7,IF($BK$8=L22,8,"")))))))) -> 6 | AS22: =IF($BK$10=E22,1, IF($BK$10=F22,2, IF($BK$10=G22,3,IF($BK$10=H22,4, IF($BK$10=I22,5, IF($BK$10=J22,6, IF($BK$10=K22,7, IF($BK$10=L22,8,"")))))))) -> 3 | AT22: =IF(AM22="","",AM22) -> 7 | AU22: =IF(AN22="","",AN22) -> 4 | AV22: =IF(AP22="","",AP22) -> 5 | AW22: =IF(AQ22="","",AQ22) -> 2 | AX22: =IF(AL22="","",AL22) -> 1 | AY22: =IF(AO22="","",AO22) -> 8 | AZ22: =IF(AR22="","",AR22) -> 6 | BA22: =IF(AS22="","",AS22) -> 3 | BB22: =IF(AT22="","",ABS(AT22-1)) -> 6 | BC22: =IF(AU22="","",ABS(AU22-2)) -> 2 | BD22: =IF(AV22="","",ABS(AV22-3)) -> 2 | BE22: =IF(AW22="","",ABS(AW22-4)) -> 2 | BF22: =IF(AX22="","",ABS(AX22-5)) -> 4 | BG22: =IF(AY22="","",ABS(AY22-6)) -> 2 | BH22: =IF(AZ22="","",ABS(AZ22-7)) -> 1 | BI22: =IF(L22="","",ABS(BA22-8)) -> 5
A23: 21 | B23: Х | C23: 2 в | E23: черный | F23: серый | G23: зеленый | H23: коричневый | I23: красный | J23: желтый | K23: синий | L23: фиолетовый | M23: желтый | N23: фиолетовый | O23: зеленый | P23: черный | Q23: синий | R23: коричневый | S23: красный | T23: серый | U23: фиолетовый | V23: желтый | X23: желтый | Y23: фиолетовый | Z23: черный | AA23: серый | AB23: черный | AC23: фиолетовый | AD23: желтый | AE23: желтый | AF23: желтый | AG23: фиолетовый | AH23: желтый | AL23: =IF($BK$3=E23,1,IF($BK$3=F23,2,IF($BK$3=G23,3,IF($BK$3=H23,4,IF($BK$3=I23,5,IF($BK$3=J23,6,IF($BK$3=K23,7,IF($BK$3=L23,8,"")))))))) -> 7 | AM23: =IF($BK$4=E23,1,IF($BK$4=F23,2,IF($BK$4=G23,3,IF($BK$4=H23,4,IF($BK$4=I23,5,IF($BK$4=J23,6,IF($BK$4=K23,7,IF($BK$4=L23,8,"")))))))) -> 5 | AN23: =IF($BK$5=E23,1, IF($BK$5=F23,2, IF($BK$5=G23,3,IF($BK$5=H23,4, IF($BK$5=I23,5, IF($BK$5=J23,6, IF($BK$5=K23,7, IF($BK$5=L23,8,"")))))))) -> 6 | AO23: =IF($BK$9=E23,1, IF($BK$9=F23,2, IF($BK$9=G23,3,IF($BK$9=H23,4, IF($BK$9=I23,5, IF($BK$9=J23,6, IF($BK$9=K23,7,IF($BK$9=L23,8,"")))))))) -> 4 | AP23: =IF($BK$6=E23,1,IF($BK$6=F23,2,IF($BK$6=G23,3,IF($BK$6=H23,4,IF($BK$6=I23,5,IF($BK$6=J23,6,IF($BK$6=K23,7,IF($BK$6=L23,8,"")))))))) -> 3 | AQ23: =IF($BK$7=E23,1,IF($BK$7=F23,2,IF($BK$7=G23,3,IF($BK$7=H23,4,IF($BK$7=I23,5,IF($BK$7=J23,6,IF($BK$7=K23,7,IF($BK$7=L23,8,"")))))))) -> 8 | AR23: =IF($BK$8=E23,1, IF($BK$8=F23,2, IF($BK$8=G23,3,IF($BK$8=H23,4, IF($BK$8=I23,5, IF($BK$8=J23,6, IF($BK$8=K23,7,IF($BK$8=L23,8,"")))))))) -> 2 | AS23: =IF($BK$10=E23,1, IF($BK$10=F23,2, IF($BK$10=G23,3,IF($BK$10=H23,4, IF($BK$10=I23,5, IF($BK$10=J23,6, IF($BK$10=K23,7, IF($BK$10=L23,8,"")))))))) -> 1 | AT23: =IF(AM23="","",AM23) -> 5 | AU23: =IF(AN23="","",AN23) -> 6 | AV23: =IF(AP23="","",AP23) -> 3 | AW23: =IF(AQ23="","",AQ23) -> 8 | AX23: =IF(AL23="","",AL23) -> 7 | AY23: =IF(AO23="","",AO23) -> 4 | AZ23: =IF(AR23="","",AR23) -> 2 | BA23: =IF(AS23="","",AS23) -> 1 | BB23: =IF(AT23="","",ABS(AT23-1)) -> 4 | BC23: =IF(AU23="","",ABS(AU23-2)) -> 4 | BD23: =IF(AV23="","",ABS(AV23-3)) -> 0 | BE23: =IF(AW23="","",ABS(AW23-4)) -> 4 | BF23: =IF(AX23="","",ABS(AX23-5)) -> 2 | BG23: =IF(AY23="","",ABS(AY23-6)) -> 2 | BH23: =IF(AZ23="","",ABS(AZ23-7)) -> 5 | BI23: =IF(L23="","",ABS(BA23-8)) -> 7
... A26: 24 | B26: Ш | C26: 2 в | E26: синий | F26: зеленый | G26: красный | H26: желтый | I26: фиолетовый | J26: серый | K26: коричневый | L26: черный | M26: желтый | N26: черный | O26: зеленый | P26: фиолетовый | Q26: синий | R26: красный | S26: синий | T26: серый | U26: коричневый | V26: зеленый | X26: черный | Y26: красный | Z26: серый | AA26: коричневый | AB26: черный | AC26: синий | AD26: зеленый | AE26: синий | AF26: синий | AG26: черный | AH26: черный | AL26: =IF($BK$3=E26,1,IF($BK$3=F26,2,IF($BK$3=G26,3,IF($BK$3=H26,4,IF($BK$3=I26,5,IF($BK$3=J26,6,IF($BK$3=K26,7,IF($BK$3=L26,8,"")))))))) -> 1 | AM26: =IF($BK$4=E26,1,IF($BK$4=F26,2,IF($BK$4=G26,3,IF($BK$4=H26,4,IF($BK$4=I26,5,IF($BK$4=J26,6,IF($BK$4=K26,7,IF($BK$4=L26,8,"")))))))) -> 3 | AN26: =IF($BK$5=E26,1, IF($BK$5=F26,2, IF($BK$5=G26,3,IF($BK$5=H26,4, IF($BK$5=I26,5, IF($BK$5=J26,6, IF($BK$5=K26,7, IF($BK$5=L26,8,"")))))))) -> 4 | AO26: =IF($BK$9=E26,1, IF($BK$9=F26,2, IF($BK$9=G26,3,IF($BK$9=H26,4, IF($BK$9=I26,5, IF($BK$9=J26,6, IF($BK$9=K26,7,IF($BK$9=L26,8,"")))))))) -> 7 | AP26: =IF($BK$6=E26,1,IF($BK$6=F26,2,IF($BK$6=G26,3,IF($BK$6=H26,4,IF($BK$6=I26,5,IF($BK$6=J26,6,IF($BK$6=K26,7,IF($BK$6=L26,8,"")))))))) -> 2 | AQ26: =IF($BK$7=E26,1,IF($BK$7=F26,2,IF($BK$7=G26,3,IF($BK$7=H26,4,IF($BK$7=I26,5,IF($BK$7=J26,6,IF($BK$7=K26,7,IF($BK$7=L26,8,"")))))))) -> 5 | AR26: =IF($BK$8=E26,1, IF($BK$8=F26,2, IF($BK$8=G26,3,IF($BK$8=H26,4, IF($BK$8=I26,5, IF($BK$8=J26,6, IF($BK$8=K26,7,IF($BK$8=L26,8,"")))))))) -> 6 | AS26: =IF($BK$10=E26,1, IF($BK$10=F26,2, IF($BK$10=G26,3,IF($BK$10=H26,4, IF($BK$10=I26,5, IF($BK$10=J26,6, IF($BK$10=K26,7, IF($BK$10=L26,8,"")))))))) -> 8 | AT26: =IF(AM26="","",AM26) -> 3 | AU26: =IF(AN26="","",AN26) -> 4 | AV26: =IF(AP26="","",AP26) -> 2 | AW26: =IF(AQ26="","",AQ26) -> 5 | AX26: =IF(AL26="","",AL26) -> 1 | AY26: =IF(AO26="","",AO26) -> 7 | AZ26: =IF(AR26="","",AR26) -> 6 | BA26: =IF(AS26="","",AS26) -> 8 | BB26: =IF(AT26="","",ABS(AT26-1)) -> 2 | BC26: =IF(AU26="","",ABS(AU26-2)) -> 2 | BD26: =IF(AV26="","",ABS(AV26-3)) -> 1 | BE26: =IF(AW26="","",ABS(AW26-4)) -> 1 | BF26: =IF(AX26="","",ABS(AX26-5)) -> 4 | BG26: =IF(AY26="","",ABS(AY26-6)) -> 1 | BH26: =IF(AZ26="","",ABS(AZ26-7)) -> 1 | BI26: =IF(L26="","",ABS(BA26-8)) -> 0
A27: 25 | B27: Щ | C27: 2 в | AL27: =IF($BK$3=E27,1,IF($BK$3=F27,2,IF($BK$3=G27,3,IF($BK$3=H27,4,IF($BK$3=I27,5,IF($BK$3=J27,6,IF($BK$3=K27,7,IF($BK$3=L27,8,"")))))))) | AM27: =IF($BK$4=E27,1,IF($BK$4=F27,2,IF($BK$4=G27,3,IF($BK$4=H27,4,IF($BK$4=I27,5,IF($BK$4=J27,6,IF($BK$4=K27,7,IF($BK$4=L27,8,"")))))))) | AN27: =IF($BK$5=E27,1, IF($BK$5=F27,2, IF($BK$5=G27,3,IF($BK$5=H27,4, IF($BK$5=I27,5, IF($BK$5=J27,6, IF($BK$5=K27,7, IF($BK$5=L27,8,"")))))))) | AO27: =IF($BK$9=E27,1, IF($BK$9=F27,2, IF($BK$9=G27,3,IF($BK$9=H27,4, IF($BK$9=I27,5, IF($BK$9=J27,6, IF($BK$9=K27,7,IF($BK$9=L27,8,"")))))))) | AP27: =IF($BK$6=E27,1,IF($BK$6=F27,2,IF($BK$6=G27,3,IF($BK$6=H27,4,IF($BK$6=I27,5,IF($BK$6=J27,6,IF($BK$6=K27,7,IF($BK$6=L27,8,"")))))))) | AQ27: =IF($BK$7=E27,1,IF($BK$7=F27,2,IF($BK$7=G27,3,IF($BK$7=H27,4,IF($BK$7=I27,5,IF($BK$7=J27,6,IF($BK$7=K27,7,IF($BK$7=L27,8,"")))))))) | AR27: =IF($BK$8=E27,1, IF($BK$8=F27,2, IF($BK$8=G27,3,IF($BK$8=H27,4, IF($BK$8=I27,5, IF($BK$8=J27,6, IF($BK$8=K27,7,IF($BK$8=L27,8,"")))))))) | AS27: =IF($BK$10=E27,1, IF($BK$10=F27,2, IF($BK$10=G27,3,IF($BK$10=H27,4, IF($BK$10=I27,5, IF($BK$10=J27,6, IF($BK$10=K27,7, IF($BK$10=L27,8,"")))))))) | AT27: =IF(AM27="","",AM27) | AU27: =IF(AN27="","",AN27) | AV27: =IF(AP27="","",AP27) | AW27: =IF(AQ27="","",AQ27) | AX27: =IF(AL27="","",AL27) | AY27: =IF(AO27="","",AO27) | AZ27: =IF(AR27="","",AR27) | BA27: =IF(AS27="","",AS27) | BB27: =IF(AT27="","",ABS(AT27-1)) | BC27: =IF(AU27="","",ABS(AU27-2)) | BD27: =IF(AV27="","",ABS(AV27-3)) | BE27: =IF(AW27="","",ABS(AW27-4)) | BF27: =IF(AX27="","",ABS(AX27-5)) | BG27: =IF(AY27="","",ABS(AY27-6)) | BH27: =IF(AZ27="","",ABS(AZ27-7)) | BI27: =IF(L27="","",ABS(BA27-8))

Sheet 1_обработка CО,ВК,ЭК
E1: Задание 1 | J1: Задание 2 | T1: Задание 3
B2: ФИО ребенка | C2: класс | D2: Дата | E2: Эмоциональный фон | G2: Вегетативный компонент | I2: Самооценка
A4: =ЦТО!A3 -> 1 | B4: =ЦТО!B3 -> А | C4: =ЦТО!C3 -> 2 а | D4: =ЦТО!D3 -> 0 | E4: =SUM(ЦТО!BB3:BI3) -> 0 | F4: =IF(E4<10,'вспомогательные данные'!$C$26,IF(E4<19,'вспомогательные данные'!$C$25,'вспомогательные данные'!$C$24)) -> положительный | G4: =(18-ЦТО!AM3-ЦТО!AL3)/(18-ЦТО!AL3-ЦТО!AP3) -> #VALUE! | H4: =IF(G4<0.51,'вспомогательные данные'!$C$19,IF(G4<0.92,'вспомогательные данные'!$C$20, IF(G4<2,'вспомогательные данные'!$C$21,'вспомогательные данные'!$C$22))) -> #VALUE! | I4: =IF(OR(ЦТО!AT3=1,ЦТО!AU3=1,ЦТО!AV3=1,ЦТО!AX3=1),"Положительная",IF(OR(ЦТО!AY3=1,ЦТО!AZ3=1,ЦТО!BA3=1),"Отрицательная",IF(OR(ЦТО!AW3=1),"Инфантильная"))) -> FALSE
A5: =ЦТО!A4 -> 2 | B5: =ЦТО!B4 -> Б | C5: =ЦТО!C4 -> 2 а | D5: =ЦТО!D4 -> 0 | E5: =SUM(ЦТО!BB4:BI4) -> 20 | F5: =IF(E5<10,'вспомогательные данные'!$C$26,IF(E5<19,'вспомогательные данные'!$C$25,'вспомогательные данные'!$C$24)) -> отрицательный | G5: =(18-ЦТО!AM4-ЦТО!AL4)/(18-ЦТО!AL4-ЦТО!AP4) -> 1.1818182 | H5: =IF(G5<0.51,'вспомогательные данные'!$C$19,IF(G5<0.92,'вспомогательные данные'!$C$20, IF(G5<2,'вспомогательные данные'!$C$21,'вспомогательные данные'!$C$22))) -> оптимальная работоспособность | I5: =IF(OR(ЦТО!AT4=1,ЦТО!AU4=1,ЦТО!AV4=1,ЦТО!AX4=1),"Положительная",IF(OR(ЦТО!AY4=1,ЦТО!AZ4=1,ЦТО!BA4=1),"Отрицательная",IF(OR(ЦТО!AW4=1),"Инфантильная"))) -> Инфантильная
A6: =ЦТО!A5 -> 3 | B6: =ЦТО!B5 -> В | C6: =ЦТО!C5 -> 2 а | D6: =ЦТО!D5 -> 0 | E6: =SUM(ЦТО!BB5:BI5) -> 24 | F6: =IF(E6<10,'вспомогательные данные'!$C$26,IF(E6<19,'вспомогательные данные'!$C$25,'вспомогательные данные'!$C$24)) -> отрицательный | G6: =(18-ЦТО!AM5-ЦТО!AL5)/(18-ЦТО!AL5-ЦТО!AP5) -> 0.69230769 | H6: =IF(G6<0.51,'вспомогательные данные'!$C$19,IF(G6<0.92,'вспомогательные данные'!$C$20, IF(G6<2,'вспомогательные данные'!$C$21,'вспомогательные данные'!$C$22))) -> усталость | I6: =IF(OR(ЦТО!AT5=1,ЦТО!AU5=1,ЦТО!AV5=1,ЦТО!AX5=1),"Положительная",IF(OR(ЦТО!AY5=1,ЦТО!AZ5=1,ЦТО!BA5=1),"Отрицательная",IF(OR(ЦТО!AW5=1),"Инфантильная"))) -> Инфантильная
A7: =ЦТО!A6 -> 4 | B7: =ЦТО!B6 -> Г | C7: =ЦТО!C6 -> 2 а | D7: =ЦТО!D6 -> 0 | E7: =SUM(ЦТО!BB6:BI6) -> 16 | F7: =IF(E7<10,'вспомогательные данные'!$C$26,IF(E7<19,'вспомогательные данные'!$C$25,'вспомогательные данные'!$C$24)) -> нормальный | G7: =(18-ЦТО!AM6-ЦТО!AL6)/(18-ЦТО!AL6-ЦТО!AP6) -> 1.4444444 | H7: =IF(G7<0.51,'вспомогательные данные'!$C$19,IF(G7<0.92,'вспомогательные данные'!$C$20, IF(G7<2,'вспомогательные данные'!$C$21,'вспомогательные данные'!$C$22))) -> оптимальная работоспособность | I7: =IF(OR(ЦТО!AT6=1,ЦТО!AU6=1,ЦТО!AV6=1,ЦТО!AX6=1),"Положительная",IF(OR(ЦТО!AY6=1,ЦТО!AZ6=1,ЦТО!BA6=1),"Отрицательная",IF(OR(ЦТО!AW6=1),"Инфантильная"))) -> Положительная
A8: =ЦТО!A7 -> 5 | B8: =ЦТО!B7 -> Д | C8: =ЦТО!C7 -> 2 а | D8: =ЦТО!D7 -> 0 | E8: =SUM(ЦТО!BB7:BI7) -> 16 | F8: =IF(E8<10,'вспомогательные данные'!$C$26,IF(E8<19,'вспомогательные данные'!$C$25,'вспомогательные данные'!$C$24)) -> нормальный | G8: =(18-ЦТО!AM7-ЦТО!AL7)/(18-ЦТО!AL7-ЦТО!AP7) -> 1.2857143 | H8: =IF(G8<0.51,'вспомогательные данные'!$C$19,IF(G8<0.92,'вспомогательные данные'!$C$20, IF(G8<2,'вспомогательные данные'!$C$21,'вспомогательные данные'!$C$22))) -> оптимальная работоспособность | I8: =IF(OR(ЦТО!AT7=1,ЦТО!AU7=1,ЦТО!AV7=1,ЦТО!AX7=1),"Положительная",IF(OR(ЦТО!AY7=1,ЦТО!AZ7=1,ЦТО!BA7=1),"Отрицательная",IF(OR(ЦТО!AW7=1),"Инфантильная"))) -> Положительная
A9: =ЦТО!A8 -> 6 | B9: =ЦТО!B8 -> Е | C9: =ЦТО!C8 -> 2 а | D9: =ЦТО!D8 -> 0 | E9: =SUM(ЦТО!BB8:BI8) -> 0 | F9: =IF(E9<10,'вспомогательные данные'!$C$26,IF(E9<19,'вспомогательные данные'!$C$25,'вспомогательные данные'!$C$24)) -> положительный | G9: =(18-ЦТО!AM8-ЦТО!AL8)/(18-ЦТО!AL8-ЦТО!AP8) -> #VALUE! | H9: =IF(G9<0.51,'вспомогательные данные'!$C$19,IF(G9<0.92,'вспомогательные данные'!$C$20, IF(G9<2,'вспомогательные данные'!$C$21,'вспомогательные данные'!$C$22))) -> #VALUE! | I9: =IF(OR(ЦТО!AT8=1,ЦТО!AU8=1,ЦТО!AV8=1,ЦТО!AX8=1),"Положительная",IF(OR(ЦТО!AY8=1,ЦТО!AZ8=1,ЦТО!BA8=1),"Отрицательная",IF(OR(ЦТО!AW8=1),"Инфантильная"))) -> FALSE
A10: =ЦТО!A9 -> 7 | B10: =ЦТО!B9 -> Ж | C10: =ЦТО!C9 -> 2 а | D10: =ЦТО!D9 -> 0 | E10: =SUM(ЦТО!BB9:BI9) -> 18 | F10: =IF(E10<10,'вспомогательные данные'!$C$26,IF(E10<19,'вспомогательные данные'!$C$25,'вспомогательные данные'!$C$24)) -> нормальный | G10: =(18-ЦТО!AM9-ЦТО!AL9)/(18-ЦТО!AL9-ЦТО!AP9) -> 1.2 | H10: =IF(G10<0.51,'вспомогательные данные'!$C$19,IF(G10<0.92,'вспомогательные данные'!$C$20, IF(G10<2,'вспомогательные данные'!$C$21,'вспомогательные данные'!$C$22))) -> оптимальная работоспособность | I10: =IF(OR(ЦТО!AT9=1,ЦТО!AU9=1,ЦТО!AV9=1,ЦТО!AX9=1),"Положительная",IF(OR(ЦТО!AY9=1,ЦТО!AZ9=1,ЦТО!BA9=1),"Отрицательная",IF(OR(ЦТО!AW9=1),"Инфантильная"))) -> Инфантильная
A11: =ЦТО!A10 -> 8 | B11: =ЦТО!B10 -> З | C11: =ЦТО!C10 -> 2 а | D11: =ЦТО!D10 -> 0 | E11: =SUM(ЦТО!BB10:BI10) -> 22 | F11: =IF(E11<10,'вспомогательные данные'!$C$26,IF(E11<19,'вспомогательные данные'!$C$25,'вспомогательные данные'!$C$24)) -> отрицательный | G11: =(18-ЦТО!AM10-ЦТО!AL10)/(18-ЦТО!AL10-ЦТО!AP10) -> 1.2222222 | H11: =IF(G11<0.51,'вспомогательные данные'!$C$19,IF(G11<0.92,'вспомогательные данные'!$C$20, IF(G11<2,'вспомогательные данные'!$C$21,'вспомогательные данные'!$C$22))) -> оптимальная работоспособность | I11: =IF(OR(ЦТО!AT10=1,ЦТО!AU10=1,ЦТО!AV10=1,ЦТО!AX10=1),"Положительная",IF(OR(ЦТО!AY10=1,ЦТО!AZ10=1,ЦТО!BA10=1),"Отрицательная",IF(OR(ЦТО!AW10=1),"Инфантильная"))) -> Положительная
A12: =ЦТО!A11 -> 9 | B12: =ЦТО!B11 -> И | C12: =ЦТО!C11 -> 2 а | D12: =ЦТО!D11 -> 0 | E12: =SUM(ЦТО!BB11:BI11) -> 16 | F12: =IF(E12<10,'вспомогательные данные'!$C$26,IF(E12<19,'вспомогательные данные'!$C$25,'вспомогательные данные'!$C$24)) -> нормальный | G12: =(18-ЦТО!AM11-ЦТО!AL11)/(18-ЦТО!AL11-ЦТО!AP11) -> 0.93333333 | H12: =IF(G12<0.51,'вспомогательные данные'!$C$19,IF(G12<0.92,'вспомогательные данные'!$C$20, IF(G12<2,'вспомогательные данные'!$C$21,'вспомогательные данные'!$C$22))) -> оптимальная работоспособность | I12: =IF(OR(ЦТО!AT11=1,ЦТО!AU11=1,ЦТО!AV11=1,ЦТО!AX11=1),"Положительная",IF(OR(ЦТО!AY11=1,ЦТО!AZ11=1,ЦТО!BA11=1),"Отрицательная",IF(OR(ЦТО!AW11=1),"Инфантильная"))) -> Положительная
A13: =ЦТО!A12 -> 10 | B13: =ЦТО!B12 -> К | C13: =ЦТО!C12 -> 2 а | D13: =ЦТО!D12 -> 0 | E13: =SUM(ЦТО!BB12:BI12) -> 18 | F13: =IF(E13<10,'вспомогательные данные'!$C$26,IF(E13<19,'вспомогательные данные'!$C$25,'вспомогательные данные'!$C$24)) -> нормальный | G13: =(18-ЦТО!AM12-ЦТО!AL12)/(18-ЦТО!AL12-ЦТО!AP12) -> 0.91666667 | H13: =IF(G13<0.51,'вспомогательные данные'!$C$19,IF(G13<0.92,'вспомогательные данные'!$C$20, IF(G13<2,'вспомогательные данные'!$C$21,'вспомогательные данные'!$C$22))) -> усталость | I13: =IF(OR(ЦТО!AT12=1,ЦТО!AU12=1,ЦТО!AV12=1,ЦТО!AX12=1),"Положительная",IF(OR(ЦТО!AY12=1,ЦТО!AZ12=1,ЦТО!BA12=1),"Отрицательная",IF(OR(ЦТО!AW12=1),"Инфантильная"))) -> Положительная
A14: =ЦТО!A13 -> 11 | B14: =ЦТО!B13 -> Л | C14: =ЦТО!C13 -> 2 а | D14: =ЦТО!D13 -> 0 | E14: =SUM(ЦТО!BB13:BI13) -> 24 | F14: =IF(E14<10,'вспомогательные данные'!$C$26,IF(E14<19,'вспомогательные данные'!$C$25,'вспомогательные данные'!$C$24)) -> отрицательный | G14: =(18-ЦТО!AM13-ЦТО!AL13)/(18-ЦТО!AL13-ЦТО!AP13) -> 0.64285714 | H14: =IF(G14<0.51,'вспомогательные данные'!$C$19,IF(G14<0.92,'вспомогательные данные'!$C$20, IF(G14<2,'вспомогательные данные'!$C$21,'вспомогательные данные'!$C$22))) -> усталость | I14: =IF(OR(ЦТО!AT13=1,ЦТО!AU13=1,ЦТО!AV13=1,ЦТО!AX13=1),"Положительная",IF(OR(ЦТО!AY13=1,ЦТО!AZ13=1,ЦТО!BA13=1),"Отрицательная",IF(OR(ЦТО!AW13=1),"Инфантильная"))) -> Положительная
A15: =ЦТО!A14 -> 12 | B15: =ЦТО!B14 -> М | C15: =ЦТО!C14 -> 2 а | D15: =ЦТО!D14 -> 0 | E15: =SUM(ЦТО!BB14:BI14) -> 22 | F15: =IF(E15<10,'вспомогательные данные'!$C$26,IF(E15<19,'вспомогательные данные'!$C$25,'вспомогательные данные'!$C$24)) -> отрицательный | G15: =(18-ЦТО!AM14-ЦТО!AL14)/(18-ЦТО!AL14-ЦТО!AP14) -> 1.8 | H15: =IF(G15<0.51,'вспомогательные данные'!$C$19,IF(G15<0.92,'вспомогательные данные'!$C$20, IF(G15<2,'вспомогательные данные'!$C$21,'вспомогательные данные'!$C$22))) -> оптимальная работоспособность | I15: =IF(OR(ЦТО!AT14=1,ЦТО!AU14=1,ЦТО!AV14=1,ЦТО!AX14=1),"Положительная",IF(OR(ЦТО!AY14=1,ЦТО!AZ14=1,ЦТО!BA14=1),"Отрицательная",IF(OR(ЦТО!AW14=1),"Инфантильная"))) -> Отрицательная
... A28: =ЦТО!A27 -> 25 | B28: =ЦТО!B27 -> Щ | C28: =ЦТО!C27 -> 2 в | D28: =ЦТО!D27 -> 0 | E28: =SUM(ЦТО!BB27:BI27) -> 0 | F28: =IF(E28<10,'вспомогательные данные'!$C$26,IF(E28<19,'вспомогательные данные'!$C$25,'вспомогательные данные'!$C$24)) -> положительный | G28: =(18-ЦТО!AM27-ЦТО!AL27)/(18-ЦТО!AL27-ЦТО!AP27) -> #VALUE! | H28: =IF(G28<0.51,'вспомогательные данные'!$C$19,IF(G28<0.92,'вспомогательные данные'!$C$20, IF(G28<2,'вспомогательные данные'!$C$21,'вспомогательные данные'!$C$22))) -> #VALUE! | I28: =IF(OR(ЦТО!AT27=1,ЦТО!AU27=1,ЦТО!AV27=1,ЦТО!AX27=1),"Положительная",IF(OR(ЦТО!AY27=1,ЦТО!AZ27=1,ЦТО!BA27=1),"Отрицательная",IF(OR(ЦТО!AW27=1),"Инфантильная"))) -> FALSE
